<?xml version="1.0" encoding="UTF-8"?><testsuite name="nosetests" tests="23" errors="23" failures="0" skip="0"><testcase classname="&lt;nose.suite" name="ContextSuite context=BaseViewTest&gt;:setup" time="0.000"><error type="django.db.utils.OperationalError" message="(1045, &quot;Access denied for user 'gouser'@'10.106.104.80' (using password: YES)&quot;)&#10;-------------------- &gt;&gt; begin captured logging &lt;&lt; --------------------&#10;raven.contrib.django.client.DjangoClient: DEBUG: Sending message of length 2296 to https://bugs.goibibo.com/api/7/store/&#10;api.utils.base_utils: CRITICAL: Failed at get_config_params :::: (1045, &quot;Access denied for user 'gouser'@'10.106.104.80' (using password: YES)&quot;)&#10;faker.factory: DEBUG: Not in REPL -&gt; leaving logger event level as is.&#10;raven.contrib.django.client.DjangoClient: DEBUG: Sending message of length 2286 to https://bugs.goibibo.com/api/7/store/&#10;api.utils.base_utils: CRITICAL: Failed at get_config_params :::: (1045, &quot;Access denied for user 'gouser'@'10.106.104.80' (using password: YES)&quot;)&#10;--------------------- &gt;&gt; end captured logging &lt;&lt; ---------------------"><![CDATA[  File "/usr/local/python3/lib/python3.6/site-packages/nose/suite.py", line 210, in run
    self.setUp()
  File "/usr/local/python3/lib/python3.6/site-packages/nose/suite.py", line 293, in setUp
    self.setupContext(ancestor)
  File "/usr/local/python3/lib/python3.6/site-packages/nose/suite.py", line 316, in setupContext
    try_run(context, names)
  File "/usr/local/python3/lib/python3.6/site-packages/nose/util.py", line 471, in try_run
    return func()
  File "/usr/local/python3/lib/python3.6/site-packages/django/test/testcases.py", line 1005, in setUpClass
    if not connections_support_transactions():
  File "/usr/local/python3/lib/python3.6/site-packages/django/test/testcases.py", line 970, in connections_support_transactions
    return all(conn.features.supports_transactions for conn in connections.all())
  File "/usr/local/python3/lib/python3.6/site-packages/django/test/testcases.py", line 970, in <genexpr>
    return all(conn.features.supports_transactions for conn in connections.all())
  File "/usr/local/python3/lib/python3.6/site-packages/django/utils/functional.py", line 37, in __get__
    res = instance.__dict__[self.name] = self.func(instance)
  File "/usr/local/python3/lib/python3.6/site-packages/django/db/backends/mysql/features.py", line 101, in supports_transactions
    return self._mysql_storage_engine != 'MyISAM'
  File "/usr/local/python3/lib/python3.6/site-packages/django/utils/functional.py", line 37, in __get__
    res = instance.__dict__[self.name] = self.func(instance)
  File "/usr/local/python3/lib/python3.6/site-packages/django/db/backends/mysql/features.py", line 57, in _mysql_storage_engine
    with self.connection.cursor() as cursor:
  File "/usr/local/python3/lib/python3.6/site-packages/django/db/backends/base/base.py", line 255, in cursor
    return self._cursor()
  File "/usr/local/python3/lib/python3.6/site-packages/django/db/backends/base/base.py", line 232, in _cursor
    self.ensure_connection()
  File "/usr/local/python3/lib/python3.6/site-packages/django/db/backends/base/base.py", line 216, in ensure_connection
    self.connect()
  File "/usr/local/python3/lib/python3.6/site-packages/django/db/utils.py", line 89, in __exit__
    raise dj_exc_value.with_traceback(traceback) from exc_value
  File "/usr/local/python3/lib/python3.6/site-packages/django/db/backends/base/base.py", line 216, in ensure_connection
    self.connect()
  File "/usr/local/python3/lib/python3.6/site-packages/django/db/backends/base/base.py", line 194, in connect
    self.connection = self.get_new_connection(conn_params)
  File "/usr/local/python3/lib/python3.6/site-packages/django/db/backends/mysql/base.py", line 227, in get_new_connection
    return Database.connect(**conn_params)
  File "/usr/local/python3/lib/python3.6/site-packages/MySQLdb/__init__.py", line 86, in Connect
    return Connection(*args, **kwargs)
  File "/usr/local/python3/lib/python3.6/site-packages/MySQLdb/connections.py", line 204, in __init__
    super(Connection, self).__init__(*args, **kwargs2)
(1045, "Access denied for user 'gouser'@'10.106.104.80' (using password: YES)")
-------------------- >> begin captured logging << --------------------
raven.contrib.django.client.DjangoClient: DEBUG: Sending message of length 2296 to https://bugs.goibibo.com/api/7/store/
api.utils.base_utils: CRITICAL: Failed at get_config_params :::: (1045, "Access denied for user 'gouser'@'10.106.104.80' (using password: YES)")
faker.factory: DEBUG: Not in REPL -> leaving logger event level as is.
raven.contrib.django.client.DjangoClient: DEBUG: Sending message of length 2286 to https://bugs.goibibo.com/api/7/store/
api.utils.base_utils: CRITICAL: Failed at get_config_params :::: (1045, "Access denied for user 'gouser'@'10.106.104.80' (using password: YES)")
--------------------- >> end captured logging << ---------------------]]></error></testcase><testcase classname="&lt;nose.suite" name="ContextSuite context=SequenceTest&gt;:setup" time="0.000"><error type="django.db.utils.OperationalError" message="(1045, &quot;Access denied for user 'gouser'@'10.106.104.80' (using password: YES)&quot;)&#10;-------------------- &gt;&gt; begin captured logging &lt;&lt; --------------------&#10;raven.contrib.django.client.DjangoClient: DEBUG: Sending message of length 2296 to https://bugs.goibibo.com/api/7/store/&#10;api.utils.base_utils: CRITICAL: Failed at get_config_params :::: (1045, &quot;Access denied for user 'gouser'@'10.106.104.80' (using password: YES)&quot;)&#10;faker.factory: DEBUG: Not in REPL -&gt; leaving logger event level as is.&#10;raven.contrib.django.client.DjangoClient: DEBUG: Sending message of length 2286 to https://bugs.goibibo.com/api/7/store/&#10;api.utils.base_utils: CRITICAL: Failed at get_config_params :::: (1045, &quot;Access denied for user 'gouser'@'10.106.104.80' (using password: YES)&quot;)&#10;--------------------- &gt;&gt; end captured logging &lt;&lt; ---------------------"><![CDATA[  File "/usr/local/python3/lib/python3.6/site-packages/nose/suite.py", line 210, in run
    self.setUp()
  File "/usr/local/python3/lib/python3.6/site-packages/nose/suite.py", line 293, in setUp
    self.setupContext(ancestor)
  File "/usr/local/python3/lib/python3.6/site-packages/nose/suite.py", line 316, in setupContext
    try_run(context, names)
  File "/usr/local/python3/lib/python3.6/site-packages/nose/util.py", line 471, in try_run
    return func()
  File "/usr/local/python3/lib/python3.6/site-packages/django/test/testcases.py", line 1005, in setUpClass
    if not connections_support_transactions():
  File "/usr/local/python3/lib/python3.6/site-packages/django/test/testcases.py", line 970, in connections_support_transactions
    return all(conn.features.supports_transactions for conn in connections.all())
  File "/usr/local/python3/lib/python3.6/site-packages/django/test/testcases.py", line 970, in <genexpr>
    return all(conn.features.supports_transactions for conn in connections.all())
  File "/usr/local/python3/lib/python3.6/site-packages/django/utils/functional.py", line 37, in __get__
    res = instance.__dict__[self.name] = self.func(instance)
  File "/usr/local/python3/lib/python3.6/site-packages/django/db/backends/mysql/features.py", line 101, in supports_transactions
    return self._mysql_storage_engine != 'MyISAM'
  File "/usr/local/python3/lib/python3.6/site-packages/django/utils/functional.py", line 37, in __get__
    res = instance.__dict__[self.name] = self.func(instance)
  File "/usr/local/python3/lib/python3.6/site-packages/django/db/backends/mysql/features.py", line 57, in _mysql_storage_engine
    with self.connection.cursor() as cursor:
  File "/usr/local/python3/lib/python3.6/site-packages/django/db/backends/base/base.py", line 255, in cursor
    return self._cursor()
  File "/usr/local/python3/lib/python3.6/site-packages/django/db/backends/base/base.py", line 232, in _cursor
    self.ensure_connection()
  File "/usr/local/python3/lib/python3.6/site-packages/django/db/backends/base/base.py", line 216, in ensure_connection
    self.connect()
  File "/usr/local/python3/lib/python3.6/site-packages/django/db/utils.py", line 89, in __exit__
    raise dj_exc_value.with_traceback(traceback) from exc_value
  File "/usr/local/python3/lib/python3.6/site-packages/django/db/backends/base/base.py", line 216, in ensure_connection
    self.connect()
  File "/usr/local/python3/lib/python3.6/site-packages/django/db/backends/base/base.py", line 194, in connect
    self.connection = self.get_new_connection(conn_params)
  File "/usr/local/python3/lib/python3.6/site-packages/django/db/backends/mysql/base.py", line 227, in get_new_connection
    return Database.connect(**conn_params)
  File "/usr/local/python3/lib/python3.6/site-packages/MySQLdb/__init__.py", line 86, in Connect
    return Connection(*args, **kwargs)
  File "/usr/local/python3/lib/python3.6/site-packages/MySQLdb/connections.py", line 204, in __init__
    super(Connection, self).__init__(*args, **kwargs2)
(1045, "Access denied for user 'gouser'@'10.106.104.80' (using password: YES)")
-------------------- >> begin captured logging << --------------------
raven.contrib.django.client.DjangoClient: DEBUG: Sending message of length 2296 to https://bugs.goibibo.com/api/7/store/
api.utils.base_utils: CRITICAL: Failed at get_config_params :::: (1045, "Access denied for user 'gouser'@'10.106.104.80' (using password: YES)")
faker.factory: DEBUG: Not in REPL -> leaving logger event level as is.
raven.contrib.django.client.DjangoClient: DEBUG: Sending message of length 2286 to https://bugs.goibibo.com/api/7/store/
api.utils.base_utils: CRITICAL: Failed at get_config_params :::: (1045, "Access denied for user 'gouser'@'10.106.104.80' (using password: YES)")
--------------------- >> end captured logging << ---------------------]]></error></testcase><testcase classname="&lt;nose.suite" name="ContextSuite context=CommonUtilsTest&gt;:setup" time="0.000"><error type="django.db.utils.OperationalError" message="(1045, &quot;Access denied for user 'gouser'@'10.106.104.80' (using password: YES)&quot;)&#10;-------------------- &gt;&gt; begin captured logging &lt;&lt; --------------------&#10;raven.contrib.django.client.DjangoClient: DEBUG: Sending message of length 2296 to https://bugs.goibibo.com/api/7/store/&#10;api.utils.base_utils: CRITICAL: Failed at get_config_params :::: (1045, &quot;Access denied for user 'gouser'@'10.106.104.80' (using password: YES)&quot;)&#10;faker.factory: DEBUG: Not in REPL -&gt; leaving logger event level as is.&#10;raven.contrib.django.client.DjangoClient: DEBUG: Sending message of length 2286 to https://bugs.goibibo.com/api/7/store/&#10;api.utils.base_utils: CRITICAL: Failed at get_config_params :::: (1045, &quot;Access denied for user 'gouser'@'10.106.104.80' (using password: YES)&quot;)&#10;--------------------- &gt;&gt; end captured logging &lt;&lt; ---------------------"><![CDATA[  File "/usr/local/python3/lib/python3.6/site-packages/nose/suite.py", line 210, in run
    self.setUp()
  File "/usr/local/python3/lib/python3.6/site-packages/nose/suite.py", line 293, in setUp
    self.setupContext(ancestor)
  File "/usr/local/python3/lib/python3.6/site-packages/nose/suite.py", line 316, in setupContext
    try_run(context, names)
  File "/usr/local/python3/lib/python3.6/site-packages/nose/util.py", line 471, in try_run
    return func()
  File "/usr/local/python3/lib/python3.6/site-packages/django/test/testcases.py", line 1005, in setUpClass
    if not connections_support_transactions():
  File "/usr/local/python3/lib/python3.6/site-packages/django/test/testcases.py", line 970, in connections_support_transactions
    return all(conn.features.supports_transactions for conn in connections.all())
  File "/usr/local/python3/lib/python3.6/site-packages/django/test/testcases.py", line 970, in <genexpr>
    return all(conn.features.supports_transactions for conn in connections.all())
  File "/usr/local/python3/lib/python3.6/site-packages/django/utils/functional.py", line 37, in __get__
    res = instance.__dict__[self.name] = self.func(instance)
  File "/usr/local/python3/lib/python3.6/site-packages/django/db/backends/mysql/features.py", line 101, in supports_transactions
    return self._mysql_storage_engine != 'MyISAM'
  File "/usr/local/python3/lib/python3.6/site-packages/django/utils/functional.py", line 37, in __get__
    res = instance.__dict__[self.name] = self.func(instance)
  File "/usr/local/python3/lib/python3.6/site-packages/django/db/backends/mysql/features.py", line 57, in _mysql_storage_engine
    with self.connection.cursor() as cursor:
  File "/usr/local/python3/lib/python3.6/site-packages/django/db/backends/base/base.py", line 255, in cursor
    return self._cursor()
  File "/usr/local/python3/lib/python3.6/site-packages/django/db/backends/base/base.py", line 232, in _cursor
    self.ensure_connection()
  File "/usr/local/python3/lib/python3.6/site-packages/django/db/backends/base/base.py", line 216, in ensure_connection
    self.connect()
  File "/usr/local/python3/lib/python3.6/site-packages/django/db/utils.py", line 89, in __exit__
    raise dj_exc_value.with_traceback(traceback) from exc_value
  File "/usr/local/python3/lib/python3.6/site-packages/django/db/backends/base/base.py", line 216, in ensure_connection
    self.connect()
  File "/usr/local/python3/lib/python3.6/site-packages/django/db/backends/base/base.py", line 194, in connect
    self.connection = self.get_new_connection(conn_params)
  File "/usr/local/python3/lib/python3.6/site-packages/django/db/backends/mysql/base.py", line 227, in get_new_connection
    return Database.connect(**conn_params)
  File "/usr/local/python3/lib/python3.6/site-packages/MySQLdb/__init__.py", line 86, in Connect
    return Connection(*args, **kwargs)
  File "/usr/local/python3/lib/python3.6/site-packages/MySQLdb/connections.py", line 204, in __init__
    super(Connection, self).__init__(*args, **kwargs2)
(1045, "Access denied for user 'gouser'@'10.106.104.80' (using password: YES)")
-------------------- >> begin captured logging << --------------------
raven.contrib.django.client.DjangoClient: DEBUG: Sending message of length 2296 to https://bugs.goibibo.com/api/7/store/
api.utils.base_utils: CRITICAL: Failed at get_config_params :::: (1045, "Access denied for user 'gouser'@'10.106.104.80' (using password: YES)")
faker.factory: DEBUG: Not in REPL -> leaving logger event level as is.
raven.contrib.django.client.DjangoClient: DEBUG: Sending message of length 2286 to https://bugs.goibibo.com/api/7/store/
api.utils.base_utils: CRITICAL: Failed at get_config_params :::: (1045, "Access denied for user 'gouser'@'10.106.104.80' (using password: YES)")
--------------------- >> end captured logging << ---------------------]]></error></testcase><testcase classname="&lt;nose.suite" name="ContextSuite context=CovermoreRequestTest&gt;:setup" time="0.000"><error type="django.db.utils.OperationalError" message="(1045, &quot;Access denied for user 'gouser'@'10.106.104.80' (using password: YES)&quot;)&#10;-------------------- &gt;&gt; begin captured logging &lt;&lt; --------------------&#10;raven.contrib.django.client.DjangoClient: DEBUG: Sending message of length 2296 to https://bugs.goibibo.com/api/7/store/&#10;api.utils.base_utils: CRITICAL: Failed at get_config_params :::: (1045, &quot;Access denied for user 'gouser'@'10.106.104.80' (using password: YES)&quot;)&#10;faker.factory: DEBUG: Not in REPL -&gt; leaving logger event level as is.&#10;raven.contrib.django.client.DjangoClient: DEBUG: Sending message of length 2286 to https://bugs.goibibo.com/api/7/store/&#10;api.utils.base_utils: CRITICAL: Failed at get_config_params :::: (1045, &quot;Access denied for user 'gouser'@'10.106.104.80' (using password: YES)&quot;)&#10;--------------------- &gt;&gt; end captured logging &lt;&lt; ---------------------"><![CDATA[  File "/usr/local/python3/lib/python3.6/site-packages/nose/suite.py", line 210, in run
    self.setUp()
  File "/usr/local/python3/lib/python3.6/site-packages/nose/suite.py", line 293, in setUp
    self.setupContext(ancestor)
  File "/usr/local/python3/lib/python3.6/site-packages/nose/suite.py", line 316, in setupContext
    try_run(context, names)
  File "/usr/local/python3/lib/python3.6/site-packages/nose/util.py", line 471, in try_run
    return func()
  File "/usr/local/python3/lib/python3.6/site-packages/django/test/testcases.py", line 1005, in setUpClass
    if not connections_support_transactions():
  File "/usr/local/python3/lib/python3.6/site-packages/django/test/testcases.py", line 970, in connections_support_transactions
    return all(conn.features.supports_transactions for conn in connections.all())
  File "/usr/local/python3/lib/python3.6/site-packages/django/test/testcases.py", line 970, in <genexpr>
    return all(conn.features.supports_transactions for conn in connections.all())
  File "/usr/local/python3/lib/python3.6/site-packages/django/utils/functional.py", line 37, in __get__
    res = instance.__dict__[self.name] = self.func(instance)
  File "/usr/local/python3/lib/python3.6/site-packages/django/db/backends/mysql/features.py", line 101, in supports_transactions
    return self._mysql_storage_engine != 'MyISAM'
  File "/usr/local/python3/lib/python3.6/site-packages/django/utils/functional.py", line 37, in __get__
    res = instance.__dict__[self.name] = self.func(instance)
  File "/usr/local/python3/lib/python3.6/site-packages/django/db/backends/mysql/features.py", line 57, in _mysql_storage_engine
    with self.connection.cursor() as cursor:
  File "/usr/local/python3/lib/python3.6/site-packages/django/db/backends/base/base.py", line 255, in cursor
    return self._cursor()
  File "/usr/local/python3/lib/python3.6/site-packages/django/db/backends/base/base.py", line 232, in _cursor
    self.ensure_connection()
  File "/usr/local/python3/lib/python3.6/site-packages/django/db/backends/base/base.py", line 216, in ensure_connection
    self.connect()
  File "/usr/local/python3/lib/python3.6/site-packages/django/db/utils.py", line 89, in __exit__
    raise dj_exc_value.with_traceback(traceback) from exc_value
  File "/usr/local/python3/lib/python3.6/site-packages/django/db/backends/base/base.py", line 216, in ensure_connection
    self.connect()
  File "/usr/local/python3/lib/python3.6/site-packages/django/db/backends/base/base.py", line 194, in connect
    self.connection = self.get_new_connection(conn_params)
  File "/usr/local/python3/lib/python3.6/site-packages/django/db/backends/mysql/base.py", line 227, in get_new_connection
    return Database.connect(**conn_params)
  File "/usr/local/python3/lib/python3.6/site-packages/MySQLdb/__init__.py", line 86, in Connect
    return Connection(*args, **kwargs)
  File "/usr/local/python3/lib/python3.6/site-packages/MySQLdb/connections.py", line 204, in __init__
    super(Connection, self).__init__(*args, **kwargs2)
(1045, "Access denied for user 'gouser'@'10.106.104.80' (using password: YES)")
-------------------- >> begin captured logging << --------------------
raven.contrib.django.client.DjangoClient: DEBUG: Sending message of length 2296 to https://bugs.goibibo.com/api/7/store/
api.utils.base_utils: CRITICAL: Failed at get_config_params :::: (1045, "Access denied for user 'gouser'@'10.106.104.80' (using password: YES)")
faker.factory: DEBUG: Not in REPL -> leaving logger event level as is.
raven.contrib.django.client.DjangoClient: DEBUG: Sending message of length 2286 to https://bugs.goibibo.com/api/7/store/
api.utils.base_utils: CRITICAL: Failed at get_config_params :::: (1045, "Access denied for user 'gouser'@'10.106.104.80' (using password: YES)")
--------------------- >> end captured logging << ---------------------]]></error></testcase><testcase classname="&lt;nose.suite" name="ContextSuite context=CovermoreProviderTest&gt;:setup" time="0.000"><error type="django.db.utils.OperationalError" message="(1045, &quot;Access denied for user 'gouser'@'10.106.104.80' (using password: YES)&quot;)&#10;-------------------- &gt;&gt; begin captured logging &lt;&lt; --------------------&#10;raven.contrib.django.client.DjangoClient: DEBUG: Sending message of length 2296 to https://bugs.goibibo.com/api/7/store/&#10;api.utils.base_utils: CRITICAL: Failed at get_config_params :::: (1045, &quot;Access denied for user 'gouser'@'10.106.104.80' (using password: YES)&quot;)&#10;faker.factory: DEBUG: Not in REPL -&gt; leaving logger event level as is.&#10;raven.contrib.django.client.DjangoClient: DEBUG: Sending message of length 2286 to https://bugs.goibibo.com/api/7/store/&#10;api.utils.base_utils: CRITICAL: Failed at get_config_params :::: (1045, &quot;Access denied for user 'gouser'@'10.106.104.80' (using password: YES)&quot;)&#10;--------------------- &gt;&gt; end captured logging &lt;&lt; ---------------------"><![CDATA[  File "/usr/local/python3/lib/python3.6/site-packages/nose/suite.py", line 210, in run
    self.setUp()
  File "/usr/local/python3/lib/python3.6/site-packages/nose/suite.py", line 293, in setUp
    self.setupContext(ancestor)
  File "/usr/local/python3/lib/python3.6/site-packages/nose/suite.py", line 316, in setupContext
    try_run(context, names)
  File "/usr/local/python3/lib/python3.6/site-packages/nose/util.py", line 471, in try_run
    return func()
  File "/usr/local/python3/lib/python3.6/site-packages/django/test/testcases.py", line 1005, in setUpClass
    if not connections_support_transactions():
  File "/usr/local/python3/lib/python3.6/site-packages/django/test/testcases.py", line 970, in connections_support_transactions
    return all(conn.features.supports_transactions for conn in connections.all())
  File "/usr/local/python3/lib/python3.6/site-packages/django/test/testcases.py", line 970, in <genexpr>
    return all(conn.features.supports_transactions for conn in connections.all())
  File "/usr/local/python3/lib/python3.6/site-packages/django/utils/functional.py", line 37, in __get__
    res = instance.__dict__[self.name] = self.func(instance)
  File "/usr/local/python3/lib/python3.6/site-packages/django/db/backends/mysql/features.py", line 101, in supports_transactions
    return self._mysql_storage_engine != 'MyISAM'
  File "/usr/local/python3/lib/python3.6/site-packages/django/utils/functional.py", line 37, in __get__
    res = instance.__dict__[self.name] = self.func(instance)
  File "/usr/local/python3/lib/python3.6/site-packages/django/db/backends/mysql/features.py", line 57, in _mysql_storage_engine
    with self.connection.cursor() as cursor:
  File "/usr/local/python3/lib/python3.6/site-packages/django/db/backends/base/base.py", line 255, in cursor
    return self._cursor()
  File "/usr/local/python3/lib/python3.6/site-packages/django/db/backends/base/base.py", line 232, in _cursor
    self.ensure_connection()
  File "/usr/local/python3/lib/python3.6/site-packages/django/db/backends/base/base.py", line 216, in ensure_connection
    self.connect()
  File "/usr/local/python3/lib/python3.6/site-packages/django/db/utils.py", line 89, in __exit__
    raise dj_exc_value.with_traceback(traceback) from exc_value
  File "/usr/local/python3/lib/python3.6/site-packages/django/db/backends/base/base.py", line 216, in ensure_connection
    self.connect()
  File "/usr/local/python3/lib/python3.6/site-packages/django/db/backends/base/base.py", line 194, in connect
    self.connection = self.get_new_connection(conn_params)
  File "/usr/local/python3/lib/python3.6/site-packages/django/db/backends/mysql/base.py", line 227, in get_new_connection
    return Database.connect(**conn_params)
  File "/usr/local/python3/lib/python3.6/site-packages/MySQLdb/__init__.py", line 86, in Connect
    return Connection(*args, **kwargs)
  File "/usr/local/python3/lib/python3.6/site-packages/MySQLdb/connections.py", line 204, in __init__
    super(Connection, self).__init__(*args, **kwargs2)
(1045, "Access denied for user 'gouser'@'10.106.104.80' (using password: YES)")
-------------------- >> begin captured logging << --------------------
raven.contrib.django.client.DjangoClient: DEBUG: Sending message of length 2296 to https://bugs.goibibo.com/api/7/store/
api.utils.base_utils: CRITICAL: Failed at get_config_params :::: (1045, "Access denied for user 'gouser'@'10.106.104.80' (using password: YES)")
faker.factory: DEBUG: Not in REPL -> leaving logger event level as is.
raven.contrib.django.client.DjangoClient: DEBUG: Sending message of length 2286 to https://bugs.goibibo.com/api/7/store/
api.utils.base_utils: CRITICAL: Failed at get_config_params :::: (1045, "Access denied for user 'gouser'@'10.106.104.80' (using password: YES)")
--------------------- >> end captured logging << ---------------------]]></error></testcase><testcase classname="&lt;nose.suite" name="ContextSuite context=CreditReceiversTest&gt;:setup" time="0.000"><error type="django.db.utils.OperationalError" message="(1045, &quot;Access denied for user 'gouser'@'10.106.104.80' (using password: YES)&quot;)&#10;-------------------- &gt;&gt; begin captured logging &lt;&lt; --------------------&#10;raven.contrib.django.client.DjangoClient: DEBUG: Sending message of length 2296 to https://bugs.goibibo.com/api/7/store/&#10;api.utils.base_utils: CRITICAL: Failed at get_config_params :::: (1045, &quot;Access denied for user 'gouser'@'10.106.104.80' (using password: YES)&quot;)&#10;faker.factory: DEBUG: Not in REPL -&gt; leaving logger event level as is.&#10;raven.contrib.django.client.DjangoClient: DEBUG: Sending message of length 2286 to https://bugs.goibibo.com/api/7/store/&#10;api.utils.base_utils: CRITICAL: Failed at get_config_params :::: (1045, &quot;Access denied for user 'gouser'@'10.106.104.80' (using password: YES)&quot;)&#10;--------------------- &gt;&gt; end captured logging &lt;&lt; ---------------------"><![CDATA[  File "/usr/local/python3/lib/python3.6/site-packages/nose/suite.py", line 210, in run
    self.setUp()
  File "/usr/local/python3/lib/python3.6/site-packages/nose/suite.py", line 293, in setUp
    self.setupContext(ancestor)
  File "/usr/local/python3/lib/python3.6/site-packages/nose/suite.py", line 316, in setupContext
    try_run(context, names)
  File "/usr/local/python3/lib/python3.6/site-packages/nose/util.py", line 471, in try_run
    return func()
  File "/usr/local/python3/lib/python3.6/site-packages/django/test/testcases.py", line 1005, in setUpClass
    if not connections_support_transactions():
  File "/usr/local/python3/lib/python3.6/site-packages/django/test/testcases.py", line 970, in connections_support_transactions
    return all(conn.features.supports_transactions for conn in connections.all())
  File "/usr/local/python3/lib/python3.6/site-packages/django/test/testcases.py", line 970, in <genexpr>
    return all(conn.features.supports_transactions for conn in connections.all())
  File "/usr/local/python3/lib/python3.6/site-packages/django/utils/functional.py", line 37, in __get__
    res = instance.__dict__[self.name] = self.func(instance)
  File "/usr/local/python3/lib/python3.6/site-packages/django/db/backends/mysql/features.py", line 101, in supports_transactions
    return self._mysql_storage_engine != 'MyISAM'
  File "/usr/local/python3/lib/python3.6/site-packages/django/utils/functional.py", line 37, in __get__
    res = instance.__dict__[self.name] = self.func(instance)
  File "/usr/local/python3/lib/python3.6/site-packages/django/db/backends/mysql/features.py", line 57, in _mysql_storage_engine
    with self.connection.cursor() as cursor:
  File "/usr/local/python3/lib/python3.6/site-packages/django/db/backends/base/base.py", line 255, in cursor
    return self._cursor()
  File "/usr/local/python3/lib/python3.6/site-packages/django/db/backends/base/base.py", line 232, in _cursor
    self.ensure_connection()
  File "/usr/local/python3/lib/python3.6/site-packages/django/db/backends/base/base.py", line 216, in ensure_connection
    self.connect()
  File "/usr/local/python3/lib/python3.6/site-packages/django/db/utils.py", line 89, in __exit__
    raise dj_exc_value.with_traceback(traceback) from exc_value
  File "/usr/local/python3/lib/python3.6/site-packages/django/db/backends/base/base.py", line 216, in ensure_connection
    self.connect()
  File "/usr/local/python3/lib/python3.6/site-packages/django/db/backends/base/base.py", line 194, in connect
    self.connection = self.get_new_connection(conn_params)
  File "/usr/local/python3/lib/python3.6/site-packages/django/db/backends/mysql/base.py", line 227, in get_new_connection
    return Database.connect(**conn_params)
  File "/usr/local/python3/lib/python3.6/site-packages/MySQLdb/__init__.py", line 86, in Connect
    return Connection(*args, **kwargs)
  File "/usr/local/python3/lib/python3.6/site-packages/MySQLdb/connections.py", line 204, in __init__
    super(Connection, self).__init__(*args, **kwargs2)
(1045, "Access denied for user 'gouser'@'10.106.104.80' (using password: YES)")
-------------------- >> begin captured logging << --------------------
raven.contrib.django.client.DjangoClient: DEBUG: Sending message of length 2296 to https://bugs.goibibo.com/api/7/store/
api.utils.base_utils: CRITICAL: Failed at get_config_params :::: (1045, "Access denied for user 'gouser'@'10.106.104.80' (using password: YES)")
faker.factory: DEBUG: Not in REPL -> leaving logger event level as is.
raven.contrib.django.client.DjangoClient: DEBUG: Sending message of length 2286 to https://bugs.goibibo.com/api/7/store/
api.utils.base_utils: CRITICAL: Failed at get_config_params :::: (1045, "Access denied for user 'gouser'@'10.106.104.80' (using password: YES)")
--------------------- >> end captured logging << ---------------------]]></error></testcase><testcase classname="&lt;nose.suite" name="ContextSuite context=FiloMainTest&gt;:setup" time="0.000"><error type="django.db.utils.OperationalError" message="(1045, &quot;Access denied for user 'gouser'@'10.106.104.80' (using password: YES)&quot;)&#10;-------------------- &gt;&gt; begin captured logging &lt;&lt; --------------------&#10;raven.contrib.django.client.DjangoClient: DEBUG: Sending message of length 2296 to https://bugs.goibibo.com/api/7/store/&#10;api.utils.base_utils: CRITICAL: Failed at get_config_params :::: (1045, &quot;Access denied for user 'gouser'@'10.106.104.80' (using password: YES)&quot;)&#10;faker.factory: DEBUG: Not in REPL -&gt; leaving logger event level as is.&#10;raven.contrib.django.client.DjangoClient: DEBUG: Sending message of length 2286 to https://bugs.goibibo.com/api/7/store/&#10;api.utils.base_utils: CRITICAL: Failed at get_config_params :::: (1045, &quot;Access denied for user 'gouser'@'10.106.104.80' (using password: YES)&quot;)&#10;--------------------- &gt;&gt; end captured logging &lt;&lt; ---------------------"><![CDATA[  File "/usr/local/python3/lib/python3.6/site-packages/nose/suite.py", line 210, in run
    self.setUp()
  File "/usr/local/python3/lib/python3.6/site-packages/nose/suite.py", line 293, in setUp
    self.setupContext(ancestor)
  File "/usr/local/python3/lib/python3.6/site-packages/nose/suite.py", line 316, in setupContext
    try_run(context, names)
  File "/usr/local/python3/lib/python3.6/site-packages/nose/util.py", line 471, in try_run
    return func()
  File "/usr/local/python3/lib/python3.6/site-packages/django/test/testcases.py", line 1005, in setUpClass
    if not connections_support_transactions():
  File "/usr/local/python3/lib/python3.6/site-packages/django/test/testcases.py", line 970, in connections_support_transactions
    return all(conn.features.supports_transactions for conn in connections.all())
  File "/usr/local/python3/lib/python3.6/site-packages/django/test/testcases.py", line 970, in <genexpr>
    return all(conn.features.supports_transactions for conn in connections.all())
  File "/usr/local/python3/lib/python3.6/site-packages/django/utils/functional.py", line 37, in __get__
    res = instance.__dict__[self.name] = self.func(instance)
  File "/usr/local/python3/lib/python3.6/site-packages/django/db/backends/mysql/features.py", line 101, in supports_transactions
    return self._mysql_storage_engine != 'MyISAM'
  File "/usr/local/python3/lib/python3.6/site-packages/django/utils/functional.py", line 37, in __get__
    res = instance.__dict__[self.name] = self.func(instance)
  File "/usr/local/python3/lib/python3.6/site-packages/django/db/backends/mysql/features.py", line 57, in _mysql_storage_engine
    with self.connection.cursor() as cursor:
  File "/usr/local/python3/lib/python3.6/site-packages/django/db/backends/base/base.py", line 255, in cursor
    return self._cursor()
  File "/usr/local/python3/lib/python3.6/site-packages/django/db/backends/base/base.py", line 232, in _cursor
    self.ensure_connection()
  File "/usr/local/python3/lib/python3.6/site-packages/django/db/backends/base/base.py", line 216, in ensure_connection
    self.connect()
  File "/usr/local/python3/lib/python3.6/site-packages/django/db/utils.py", line 89, in __exit__
    raise dj_exc_value.with_traceback(traceback) from exc_value
  File "/usr/local/python3/lib/python3.6/site-packages/django/db/backends/base/base.py", line 216, in ensure_connection
    self.connect()
  File "/usr/local/python3/lib/python3.6/site-packages/django/db/backends/base/base.py", line 194, in connect
    self.connection = self.get_new_connection(conn_params)
  File "/usr/local/python3/lib/python3.6/site-packages/django/db/backends/mysql/base.py", line 227, in get_new_connection
    return Database.connect(**conn_params)
  File "/usr/local/python3/lib/python3.6/site-packages/MySQLdb/__init__.py", line 86, in Connect
    return Connection(*args, **kwargs)
  File "/usr/local/python3/lib/python3.6/site-packages/MySQLdb/connections.py", line 204, in __init__
    super(Connection, self).__init__(*args, **kwargs2)
(1045, "Access denied for user 'gouser'@'10.106.104.80' (using password: YES)")
-------------------- >> begin captured logging << --------------------
raven.contrib.django.client.DjangoClient: DEBUG: Sending message of length 2296 to https://bugs.goibibo.com/api/7/store/
api.utils.base_utils: CRITICAL: Failed at get_config_params :::: (1045, "Access denied for user 'gouser'@'10.106.104.80' (using password: YES)")
faker.factory: DEBUG: Not in REPL -> leaving logger event level as is.
raven.contrib.django.client.DjangoClient: DEBUG: Sending message of length 2286 to https://bugs.goibibo.com/api/7/store/
api.utils.base_utils: CRITICAL: Failed at get_config_params :::: (1045, "Access denied for user 'gouser'@'10.106.104.80' (using password: YES)")
--------------------- >> end captured logging << ---------------------]]></error></testcase><testcase classname="&lt;nose.suite" name="ContextSuite context=FlightAddonUtilsTest&gt;:setup" time="0.000"><error type="django.db.utils.OperationalError" message="(1045, &quot;Access denied for user 'gouser'@'10.106.104.80' (using password: YES)&quot;)&#10;-------------------- &gt;&gt; begin captured logging &lt;&lt; --------------------&#10;raven.contrib.django.client.DjangoClient: DEBUG: Sending message of length 2296 to https://bugs.goibibo.com/api/7/store/&#10;api.utils.base_utils: CRITICAL: Failed at get_config_params :::: (1045, &quot;Access denied for user 'gouser'@'10.106.104.80' (using password: YES)&quot;)&#10;faker.factory: DEBUG: Not in REPL -&gt; leaving logger event level as is.&#10;raven.contrib.django.client.DjangoClient: DEBUG: Sending message of length 2286 to https://bugs.goibibo.com/api/7/store/&#10;api.utils.base_utils: CRITICAL: Failed at get_config_params :::: (1045, &quot;Access denied for user 'gouser'@'10.106.104.80' (using password: YES)&quot;)&#10;--------------------- &gt;&gt; end captured logging &lt;&lt; ---------------------"><![CDATA[  File "/usr/local/python3/lib/python3.6/site-packages/nose/suite.py", line 210, in run
    self.setUp()
  File "/usr/local/python3/lib/python3.6/site-packages/nose/suite.py", line 293, in setUp
    self.setupContext(ancestor)
  File "/usr/local/python3/lib/python3.6/site-packages/nose/suite.py", line 316, in setupContext
    try_run(context, names)
  File "/usr/local/python3/lib/python3.6/site-packages/nose/util.py", line 471, in try_run
    return func()
  File "/usr/local/python3/lib/python3.6/site-packages/django/test/testcases.py", line 1005, in setUpClass
    if not connections_support_transactions():
  File "/usr/local/python3/lib/python3.6/site-packages/django/test/testcases.py", line 970, in connections_support_transactions
    return all(conn.features.supports_transactions for conn in connections.all())
  File "/usr/local/python3/lib/python3.6/site-packages/django/test/testcases.py", line 970, in <genexpr>
    return all(conn.features.supports_transactions for conn in connections.all())
  File "/usr/local/python3/lib/python3.6/site-packages/django/utils/functional.py", line 37, in __get__
    res = instance.__dict__[self.name] = self.func(instance)
  File "/usr/local/python3/lib/python3.6/site-packages/django/db/backends/mysql/features.py", line 101, in supports_transactions
    return self._mysql_storage_engine != 'MyISAM'
  File "/usr/local/python3/lib/python3.6/site-packages/django/utils/functional.py", line 37, in __get__
    res = instance.__dict__[self.name] = self.func(instance)
  File "/usr/local/python3/lib/python3.6/site-packages/django/db/backends/mysql/features.py", line 57, in _mysql_storage_engine
    with self.connection.cursor() as cursor:
  File "/usr/local/python3/lib/python3.6/site-packages/django/db/backends/base/base.py", line 255, in cursor
    return self._cursor()
  File "/usr/local/python3/lib/python3.6/site-packages/django/db/backends/base/base.py", line 232, in _cursor
    self.ensure_connection()
  File "/usr/local/python3/lib/python3.6/site-packages/django/db/backends/base/base.py", line 216, in ensure_connection
    self.connect()
  File "/usr/local/python3/lib/python3.6/site-packages/django/db/utils.py", line 89, in __exit__
    raise dj_exc_value.with_traceback(traceback) from exc_value
  File "/usr/local/python3/lib/python3.6/site-packages/django/db/backends/base/base.py", line 216, in ensure_connection
    self.connect()
  File "/usr/local/python3/lib/python3.6/site-packages/django/db/backends/base/base.py", line 194, in connect
    self.connection = self.get_new_connection(conn_params)
  File "/usr/local/python3/lib/python3.6/site-packages/django/db/backends/mysql/base.py", line 227, in get_new_connection
    return Database.connect(**conn_params)
  File "/usr/local/python3/lib/python3.6/site-packages/MySQLdb/__init__.py", line 86, in Connect
    return Connection(*args, **kwargs)
  File "/usr/local/python3/lib/python3.6/site-packages/MySQLdb/connections.py", line 204, in __init__
    super(Connection, self).__init__(*args, **kwargs2)
(1045, "Access denied for user 'gouser'@'10.106.104.80' (using password: YES)")
-------------------- >> begin captured logging << --------------------
raven.contrib.django.client.DjangoClient: DEBUG: Sending message of length 2296 to https://bugs.goibibo.com/api/7/store/
api.utils.base_utils: CRITICAL: Failed at get_config_params :::: (1045, "Access denied for user 'gouser'@'10.106.104.80' (using password: YES)")
faker.factory: DEBUG: Not in REPL -> leaving logger event level as is.
raven.contrib.django.client.DjangoClient: DEBUG: Sending message of length 2286 to https://bugs.goibibo.com/api/7/store/
api.utils.base_utils: CRITICAL: Failed at get_config_params :::: (1045, "Access denied for user 'gouser'@'10.106.104.80' (using password: YES)")
--------------------- >> end captured logging << ---------------------]]></error></testcase><testcase classname="&lt;nose.suite" name="ContextSuite context=FlightUtils&gt;:setup" time="0.000"><error type="django.db.utils.OperationalError" message="(1045, &quot;Access denied for user 'gouser'@'10.106.104.80' (using password: YES)&quot;)&#10;-------------------- &gt;&gt; begin captured logging &lt;&lt; --------------------&#10;raven.contrib.django.client.DjangoClient: DEBUG: Sending message of length 2296 to https://bugs.goibibo.com/api/7/store/&#10;api.utils.base_utils: CRITICAL: Failed at get_config_params :::: (1045, &quot;Access denied for user 'gouser'@'10.106.104.80' (using password: YES)&quot;)&#10;faker.factory: DEBUG: Not in REPL -&gt; leaving logger event level as is.&#10;raven.contrib.django.client.DjangoClient: DEBUG: Sending message of length 2286 to https://bugs.goibibo.com/api/7/store/&#10;api.utils.base_utils: CRITICAL: Failed at get_config_params :::: (1045, &quot;Access denied for user 'gouser'@'10.106.104.80' (using password: YES)&quot;)&#10;--------------------- &gt;&gt; end captured logging &lt;&lt; ---------------------"><![CDATA[  File "/usr/local/python3/lib/python3.6/site-packages/nose/suite.py", line 210, in run
    self.setUp()
  File "/usr/local/python3/lib/python3.6/site-packages/nose/suite.py", line 293, in setUp
    self.setupContext(ancestor)
  File "/usr/local/python3/lib/python3.6/site-packages/nose/suite.py", line 316, in setupContext
    try_run(context, names)
  File "/usr/local/python3/lib/python3.6/site-packages/nose/util.py", line 471, in try_run
    return func()
  File "/usr/local/python3/lib/python3.6/site-packages/django/test/testcases.py", line 1005, in setUpClass
    if not connections_support_transactions():
  File "/usr/local/python3/lib/python3.6/site-packages/django/test/testcases.py", line 970, in connections_support_transactions
    return all(conn.features.supports_transactions for conn in connections.all())
  File "/usr/local/python3/lib/python3.6/site-packages/django/test/testcases.py", line 970, in <genexpr>
    return all(conn.features.supports_transactions for conn in connections.all())
  File "/usr/local/python3/lib/python3.6/site-packages/django/utils/functional.py", line 37, in __get__
    res = instance.__dict__[self.name] = self.func(instance)
  File "/usr/local/python3/lib/python3.6/site-packages/django/db/backends/mysql/features.py", line 101, in supports_transactions
    return self._mysql_storage_engine != 'MyISAM'
  File "/usr/local/python3/lib/python3.6/site-packages/django/utils/functional.py", line 37, in __get__
    res = instance.__dict__[self.name] = self.func(instance)
  File "/usr/local/python3/lib/python3.6/site-packages/django/db/backends/mysql/features.py", line 57, in _mysql_storage_engine
    with self.connection.cursor() as cursor:
  File "/usr/local/python3/lib/python3.6/site-packages/django/db/backends/base/base.py", line 255, in cursor
    return self._cursor()
  File "/usr/local/python3/lib/python3.6/site-packages/django/db/backends/base/base.py", line 232, in _cursor
    self.ensure_connection()
  File "/usr/local/python3/lib/python3.6/site-packages/django/db/backends/base/base.py", line 216, in ensure_connection
    self.connect()
  File "/usr/local/python3/lib/python3.6/site-packages/django/db/utils.py", line 89, in __exit__
    raise dj_exc_value.with_traceback(traceback) from exc_value
  File "/usr/local/python3/lib/python3.6/site-packages/django/db/backends/base/base.py", line 216, in ensure_connection
    self.connect()
  File "/usr/local/python3/lib/python3.6/site-packages/django/db/backends/base/base.py", line 194, in connect
    self.connection = self.get_new_connection(conn_params)
  File "/usr/local/python3/lib/python3.6/site-packages/django/db/backends/mysql/base.py", line 227, in get_new_connection
    return Database.connect(**conn_params)
  File "/usr/local/python3/lib/python3.6/site-packages/MySQLdb/__init__.py", line 86, in Connect
    return Connection(*args, **kwargs)
  File "/usr/local/python3/lib/python3.6/site-packages/MySQLdb/connections.py", line 204, in __init__
    super(Connection, self).__init__(*args, **kwargs2)
(1045, "Access denied for user 'gouser'@'10.106.104.80' (using password: YES)")
-------------------- >> begin captured logging << --------------------
raven.contrib.django.client.DjangoClient: DEBUG: Sending message of length 2296 to https://bugs.goibibo.com/api/7/store/
api.utils.base_utils: CRITICAL: Failed at get_config_params :::: (1045, "Access denied for user 'gouser'@'10.106.104.80' (using password: YES)")
faker.factory: DEBUG: Not in REPL -> leaving logger event level as is.
raven.contrib.django.client.DjangoClient: DEBUG: Sending message of length 2286 to https://bugs.goibibo.com/api/7/store/
api.utils.base_utils: CRITICAL: Failed at get_config_params :::: (1045, "Access denied for user 'gouser'@'10.106.104.80' (using password: YES)")
--------------------- >> end captured logging << ---------------------]]></error></testcase><testcase classname="&lt;nose.suite" name="ContextSuite context=GocashApiRouterTest&gt;:setup" time="0.000"><error type="django.db.utils.OperationalError" message="(1045, &quot;Access denied for user 'gouser'@'10.106.104.80' (using password: YES)&quot;)&#10;-------------------- &gt;&gt; begin captured logging &lt;&lt; --------------------&#10;raven.contrib.django.client.DjangoClient: DEBUG: Sending message of length 2296 to https://bugs.goibibo.com/api/7/store/&#10;api.utils.base_utils: CRITICAL: Failed at get_config_params :::: (1045, &quot;Access denied for user 'gouser'@'10.106.104.80' (using password: YES)&quot;)&#10;faker.factory: DEBUG: Not in REPL -&gt; leaving logger event level as is.&#10;raven.contrib.django.client.DjangoClient: DEBUG: Sending message of length 2286 to https://bugs.goibibo.com/api/7/store/&#10;api.utils.base_utils: CRITICAL: Failed at get_config_params :::: (1045, &quot;Access denied for user 'gouser'@'10.106.104.80' (using password: YES)&quot;)&#10;--------------------- &gt;&gt; end captured logging &lt;&lt; ---------------------"><![CDATA[  File "/usr/local/python3/lib/python3.6/site-packages/nose/suite.py", line 210, in run
    self.setUp()
  File "/usr/local/python3/lib/python3.6/site-packages/nose/suite.py", line 293, in setUp
    self.setupContext(ancestor)
  File "/usr/local/python3/lib/python3.6/site-packages/nose/suite.py", line 316, in setupContext
    try_run(context, names)
  File "/usr/local/python3/lib/python3.6/site-packages/nose/util.py", line 471, in try_run
    return func()
  File "/usr/local/python3/lib/python3.6/site-packages/django/test/testcases.py", line 1005, in setUpClass
    if not connections_support_transactions():
  File "/usr/local/python3/lib/python3.6/site-packages/django/test/testcases.py", line 970, in connections_support_transactions
    return all(conn.features.supports_transactions for conn in connections.all())
  File "/usr/local/python3/lib/python3.6/site-packages/django/test/testcases.py", line 970, in <genexpr>
    return all(conn.features.supports_transactions for conn in connections.all())
  File "/usr/local/python3/lib/python3.6/site-packages/django/utils/functional.py", line 37, in __get__
    res = instance.__dict__[self.name] = self.func(instance)
  File "/usr/local/python3/lib/python3.6/site-packages/django/db/backends/mysql/features.py", line 101, in supports_transactions
    return self._mysql_storage_engine != 'MyISAM'
  File "/usr/local/python3/lib/python3.6/site-packages/django/utils/functional.py", line 37, in __get__
    res = instance.__dict__[self.name] = self.func(instance)
  File "/usr/local/python3/lib/python3.6/site-packages/django/db/backends/mysql/features.py", line 57, in _mysql_storage_engine
    with self.connection.cursor() as cursor:
  File "/usr/local/python3/lib/python3.6/site-packages/django/db/backends/base/base.py", line 255, in cursor
    return self._cursor()
  File "/usr/local/python3/lib/python3.6/site-packages/django/db/backends/base/base.py", line 232, in _cursor
    self.ensure_connection()
  File "/usr/local/python3/lib/python3.6/site-packages/django/db/backends/base/base.py", line 216, in ensure_connection
    self.connect()
  File "/usr/local/python3/lib/python3.6/site-packages/django/db/utils.py", line 89, in __exit__
    raise dj_exc_value.with_traceback(traceback) from exc_value
  File "/usr/local/python3/lib/python3.6/site-packages/django/db/backends/base/base.py", line 216, in ensure_connection
    self.connect()
  File "/usr/local/python3/lib/python3.6/site-packages/django/db/backends/base/base.py", line 194, in connect
    self.connection = self.get_new_connection(conn_params)
  File "/usr/local/python3/lib/python3.6/site-packages/django/db/backends/mysql/base.py", line 227, in get_new_connection
    return Database.connect(**conn_params)
  File "/usr/local/python3/lib/python3.6/site-packages/MySQLdb/__init__.py", line 86, in Connect
    return Connection(*args, **kwargs)
  File "/usr/local/python3/lib/python3.6/site-packages/MySQLdb/connections.py", line 204, in __init__
    super(Connection, self).__init__(*args, **kwargs2)
(1045, "Access denied for user 'gouser'@'10.106.104.80' (using password: YES)")
-------------------- >> begin captured logging << --------------------
raven.contrib.django.client.DjangoClient: DEBUG: Sending message of length 2296 to https://bugs.goibibo.com/api/7/store/
api.utils.base_utils: CRITICAL: Failed at get_config_params :::: (1045, "Access denied for user 'gouser'@'10.106.104.80' (using password: YES)")
faker.factory: DEBUG: Not in REPL -> leaving logger event level as is.
raven.contrib.django.client.DjangoClient: DEBUG: Sending message of length 2286 to https://bugs.goibibo.com/api/7/store/
api.utils.base_utils: CRITICAL: Failed at get_config_params :::: (1045, "Access denied for user 'gouser'@'10.106.104.80' (using password: YES)")
--------------------- >> end captured logging << ---------------------]]></error></testcase><testcase classname="&lt;nose.suite" name="ContextSuite context=PaymentDetailsTest&gt;:setup" time="0.000"><error type="django.db.utils.OperationalError" message="(1045, &quot;Access denied for user 'gouser'@'10.106.104.80' (using password: YES)&quot;)&#10;-------------------- &gt;&gt; begin captured logging &lt;&lt; --------------------&#10;raven.contrib.django.client.DjangoClient: DEBUG: Sending message of length 2296 to https://bugs.goibibo.com/api/7/store/&#10;api.utils.base_utils: CRITICAL: Failed at get_config_params :::: (1045, &quot;Access denied for user 'gouser'@'10.106.104.80' (using password: YES)&quot;)&#10;faker.factory: DEBUG: Not in REPL -&gt; leaving logger event level as is.&#10;raven.contrib.django.client.DjangoClient: DEBUG: Sending message of length 2286 to https://bugs.goibibo.com/api/7/store/&#10;api.utils.base_utils: CRITICAL: Failed at get_config_params :::: (1045, &quot;Access denied for user 'gouser'@'10.106.104.80' (using password: YES)&quot;)&#10;--------------------- &gt;&gt; end captured logging &lt;&lt; ---------------------"><![CDATA[  File "/usr/local/python3/lib/python3.6/site-packages/nose/suite.py", line 210, in run
    self.setUp()
  File "/usr/local/python3/lib/python3.6/site-packages/nose/suite.py", line 293, in setUp
    self.setupContext(ancestor)
  File "/usr/local/python3/lib/python3.6/site-packages/nose/suite.py", line 316, in setupContext
    try_run(context, names)
  File "/usr/local/python3/lib/python3.6/site-packages/nose/util.py", line 471, in try_run
    return func()
  File "/usr/local/python3/lib/python3.6/site-packages/django/test/testcases.py", line 1005, in setUpClass
    if not connections_support_transactions():
  File "/usr/local/python3/lib/python3.6/site-packages/django/test/testcases.py", line 970, in connections_support_transactions
    return all(conn.features.supports_transactions for conn in connections.all())
  File "/usr/local/python3/lib/python3.6/site-packages/django/test/testcases.py", line 970, in <genexpr>
    return all(conn.features.supports_transactions for conn in connections.all())
  File "/usr/local/python3/lib/python3.6/site-packages/django/utils/functional.py", line 37, in __get__
    res = instance.__dict__[self.name] = self.func(instance)
  File "/usr/local/python3/lib/python3.6/site-packages/django/db/backends/mysql/features.py", line 101, in supports_transactions
    return self._mysql_storage_engine != 'MyISAM'
  File "/usr/local/python3/lib/python3.6/site-packages/django/utils/functional.py", line 37, in __get__
    res = instance.__dict__[self.name] = self.func(instance)
  File "/usr/local/python3/lib/python3.6/site-packages/django/db/backends/mysql/features.py", line 57, in _mysql_storage_engine
    with self.connection.cursor() as cursor:
  File "/usr/local/python3/lib/python3.6/site-packages/django/db/backends/base/base.py", line 255, in cursor
    return self._cursor()
  File "/usr/local/python3/lib/python3.6/site-packages/django/db/backends/base/base.py", line 232, in _cursor
    self.ensure_connection()
  File "/usr/local/python3/lib/python3.6/site-packages/django/db/backends/base/base.py", line 216, in ensure_connection
    self.connect()
  File "/usr/local/python3/lib/python3.6/site-packages/django/db/utils.py", line 89, in __exit__
    raise dj_exc_value.with_traceback(traceback) from exc_value
  File "/usr/local/python3/lib/python3.6/site-packages/django/db/backends/base/base.py", line 216, in ensure_connection
    self.connect()
  File "/usr/local/python3/lib/python3.6/site-packages/django/db/backends/base/base.py", line 194, in connect
    self.connection = self.get_new_connection(conn_params)
  File "/usr/local/python3/lib/python3.6/site-packages/django/db/backends/mysql/base.py", line 227, in get_new_connection
    return Database.connect(**conn_params)
  File "/usr/local/python3/lib/python3.6/site-packages/MySQLdb/__init__.py", line 86, in Connect
    return Connection(*args, **kwargs)
  File "/usr/local/python3/lib/python3.6/site-packages/MySQLdb/connections.py", line 204, in __init__
    super(Connection, self).__init__(*args, **kwargs2)
(1045, "Access denied for user 'gouser'@'10.106.104.80' (using password: YES)")
-------------------- >> begin captured logging << --------------------
raven.contrib.django.client.DjangoClient: DEBUG: Sending message of length 2296 to https://bugs.goibibo.com/api/7/store/
api.utils.base_utils: CRITICAL: Failed at get_config_params :::: (1045, "Access denied for user 'gouser'@'10.106.104.80' (using password: YES)")
faker.factory: DEBUG: Not in REPL -> leaving logger event level as is.
raven.contrib.django.client.DjangoClient: DEBUG: Sending message of length 2286 to https://bugs.goibibo.com/api/7/store/
api.utils.base_utils: CRITICAL: Failed at get_config_params :::: (1045, "Access denied for user 'gouser'@'10.106.104.80' (using password: YES)")
--------------------- >> end captured logging << ---------------------]]></error></testcase><testcase classname="&lt;nose.suite" name="ContextSuite context=InvoiceTest&gt;:setup" time="0.000"><error type="django.db.utils.OperationalError" message="(1045, &quot;Access denied for user 'gouser'@'10.106.104.80' (using password: YES)&quot;)&#10;-------------------- &gt;&gt; begin captured logging &lt;&lt; --------------------&#10;raven.contrib.django.client.DjangoClient: DEBUG: Sending message of length 2296 to https://bugs.goibibo.com/api/7/store/&#10;api.utils.base_utils: CRITICAL: Failed at get_config_params :::: (1045, &quot;Access denied for user 'gouser'@'10.106.104.80' (using password: YES)&quot;)&#10;faker.factory: DEBUG: Not in REPL -&gt; leaving logger event level as is.&#10;raven.contrib.django.client.DjangoClient: DEBUG: Sending message of length 2286 to https://bugs.goibibo.com/api/7/store/&#10;api.utils.base_utils: CRITICAL: Failed at get_config_params :::: (1045, &quot;Access denied for user 'gouser'@'10.106.104.80' (using password: YES)&quot;)&#10;--------------------- &gt;&gt; end captured logging &lt;&lt; ---------------------"><![CDATA[  File "/usr/local/python3/lib/python3.6/site-packages/nose/suite.py", line 210, in run
    self.setUp()
  File "/usr/local/python3/lib/python3.6/site-packages/nose/suite.py", line 293, in setUp
    self.setupContext(ancestor)
  File "/usr/local/python3/lib/python3.6/site-packages/nose/suite.py", line 316, in setupContext
    try_run(context, names)
  File "/usr/local/python3/lib/python3.6/site-packages/nose/util.py", line 471, in try_run
    return func()
  File "/usr/local/python3/lib/python3.6/site-packages/django/test/testcases.py", line 1005, in setUpClass
    if not connections_support_transactions():
  File "/usr/local/python3/lib/python3.6/site-packages/django/test/testcases.py", line 970, in connections_support_transactions
    return all(conn.features.supports_transactions for conn in connections.all())
  File "/usr/local/python3/lib/python3.6/site-packages/django/test/testcases.py", line 970, in <genexpr>
    return all(conn.features.supports_transactions for conn in connections.all())
  File "/usr/local/python3/lib/python3.6/site-packages/django/utils/functional.py", line 37, in __get__
    res = instance.__dict__[self.name] = self.func(instance)
  File "/usr/local/python3/lib/python3.6/site-packages/django/db/backends/mysql/features.py", line 101, in supports_transactions
    return self._mysql_storage_engine != 'MyISAM'
  File "/usr/local/python3/lib/python3.6/site-packages/django/utils/functional.py", line 37, in __get__
    res = instance.__dict__[self.name] = self.func(instance)
  File "/usr/local/python3/lib/python3.6/site-packages/django/db/backends/mysql/features.py", line 57, in _mysql_storage_engine
    with self.connection.cursor() as cursor:
  File "/usr/local/python3/lib/python3.6/site-packages/django/db/backends/base/base.py", line 255, in cursor
    return self._cursor()
  File "/usr/local/python3/lib/python3.6/site-packages/django/db/backends/base/base.py", line 232, in _cursor
    self.ensure_connection()
  File "/usr/local/python3/lib/python3.6/site-packages/django/db/backends/base/base.py", line 216, in ensure_connection
    self.connect()
  File "/usr/local/python3/lib/python3.6/site-packages/django/db/utils.py", line 89, in __exit__
    raise dj_exc_value.with_traceback(traceback) from exc_value
  File "/usr/local/python3/lib/python3.6/site-packages/django/db/backends/base/base.py", line 216, in ensure_connection
    self.connect()
  File "/usr/local/python3/lib/python3.6/site-packages/django/db/backends/base/base.py", line 194, in connect
    self.connection = self.get_new_connection(conn_params)
  File "/usr/local/python3/lib/python3.6/site-packages/django/db/backends/mysql/base.py", line 227, in get_new_connection
    return Database.connect(**conn_params)
  File "/usr/local/python3/lib/python3.6/site-packages/MySQLdb/__init__.py", line 86, in Connect
    return Connection(*args, **kwargs)
  File "/usr/local/python3/lib/python3.6/site-packages/MySQLdb/connections.py", line 204, in __init__
    super(Connection, self).__init__(*args, **kwargs2)
(1045, "Access denied for user 'gouser'@'10.106.104.80' (using password: YES)")
-------------------- >> begin captured logging << --------------------
raven.contrib.django.client.DjangoClient: DEBUG: Sending message of length 2296 to https://bugs.goibibo.com/api/7/store/
api.utils.base_utils: CRITICAL: Failed at get_config_params :::: (1045, "Access denied for user 'gouser'@'10.106.104.80' (using password: YES)")
faker.factory: DEBUG: Not in REPL -> leaving logger event level as is.
raven.contrib.django.client.DjangoClient: DEBUG: Sending message of length 2286 to https://bugs.goibibo.com/api/7/store/
api.utils.base_utils: CRITICAL: Failed at get_config_params :::: (1045, "Access denied for user 'gouser'@'10.106.104.80' (using password: YES)")
--------------------- >> end captured logging << ---------------------]]></error></testcase><testcase classname="&lt;nose.suite" name="ContextSuite context=PeshkashConvenienceFeeTest&gt;:setup" time="0.000"><error type="django.db.utils.OperationalError" message="(1045, &quot;Access denied for user 'gouser'@'10.106.104.80' (using password: YES)&quot;)&#10;-------------------- &gt;&gt; begin captured logging &lt;&lt; --------------------&#10;raven.contrib.django.client.DjangoClient: DEBUG: Sending message of length 2296 to https://bugs.goibibo.com/api/7/store/&#10;api.utils.base_utils: CRITICAL: Failed at get_config_params :::: (1045, &quot;Access denied for user 'gouser'@'10.106.104.80' (using password: YES)&quot;)&#10;faker.factory: DEBUG: Not in REPL -&gt; leaving logger event level as is.&#10;raven.contrib.django.client.DjangoClient: DEBUG: Sending message of length 2286 to https://bugs.goibibo.com/api/7/store/&#10;api.utils.base_utils: CRITICAL: Failed at get_config_params :::: (1045, &quot;Access denied for user 'gouser'@'10.106.104.80' (using password: YES)&quot;)&#10;--------------------- &gt;&gt; end captured logging &lt;&lt; ---------------------"><![CDATA[  File "/usr/local/python3/lib/python3.6/site-packages/nose/suite.py", line 210, in run
    self.setUp()
  File "/usr/local/python3/lib/python3.6/site-packages/nose/suite.py", line 293, in setUp
    self.setupContext(ancestor)
  File "/usr/local/python3/lib/python3.6/site-packages/nose/suite.py", line 316, in setupContext
    try_run(context, names)
  File "/usr/local/python3/lib/python3.6/site-packages/nose/util.py", line 471, in try_run
    return func()
  File "/usr/local/python3/lib/python3.6/site-packages/django/test/testcases.py", line 1005, in setUpClass
    if not connections_support_transactions():
  File "/usr/local/python3/lib/python3.6/site-packages/django/test/testcases.py", line 970, in connections_support_transactions
    return all(conn.features.supports_transactions for conn in connections.all())
  File "/usr/local/python3/lib/python3.6/site-packages/django/test/testcases.py", line 970, in <genexpr>
    return all(conn.features.supports_transactions for conn in connections.all())
  File "/usr/local/python3/lib/python3.6/site-packages/django/utils/functional.py", line 37, in __get__
    res = instance.__dict__[self.name] = self.func(instance)
  File "/usr/local/python3/lib/python3.6/site-packages/django/db/backends/mysql/features.py", line 101, in supports_transactions
    return self._mysql_storage_engine != 'MyISAM'
  File "/usr/local/python3/lib/python3.6/site-packages/django/utils/functional.py", line 37, in __get__
    res = instance.__dict__[self.name] = self.func(instance)
  File "/usr/local/python3/lib/python3.6/site-packages/django/db/backends/mysql/features.py", line 57, in _mysql_storage_engine
    with self.connection.cursor() as cursor:
  File "/usr/local/python3/lib/python3.6/site-packages/django/db/backends/base/base.py", line 255, in cursor
    return self._cursor()
  File "/usr/local/python3/lib/python3.6/site-packages/django/db/backends/base/base.py", line 232, in _cursor
    self.ensure_connection()
  File "/usr/local/python3/lib/python3.6/site-packages/django/db/backends/base/base.py", line 216, in ensure_connection
    self.connect()
  File "/usr/local/python3/lib/python3.6/site-packages/django/db/utils.py", line 89, in __exit__
    raise dj_exc_value.with_traceback(traceback) from exc_value
  File "/usr/local/python3/lib/python3.6/site-packages/django/db/backends/base/base.py", line 216, in ensure_connection
    self.connect()
  File "/usr/local/python3/lib/python3.6/site-packages/django/db/backends/base/base.py", line 194, in connect
    self.connection = self.get_new_connection(conn_params)
  File "/usr/local/python3/lib/python3.6/site-packages/django/db/backends/mysql/base.py", line 227, in get_new_connection
    return Database.connect(**conn_params)
  File "/usr/local/python3/lib/python3.6/site-packages/MySQLdb/__init__.py", line 86, in Connect
    return Connection(*args, **kwargs)
  File "/usr/local/python3/lib/python3.6/site-packages/MySQLdb/connections.py", line 204, in __init__
    super(Connection, self).__init__(*args, **kwargs2)
(1045, "Access denied for user 'gouser'@'10.106.104.80' (using password: YES)")
-------------------- >> begin captured logging << --------------------
raven.contrib.django.client.DjangoClient: DEBUG: Sending message of length 2296 to https://bugs.goibibo.com/api/7/store/
api.utils.base_utils: CRITICAL: Failed at get_config_params :::: (1045, "Access denied for user 'gouser'@'10.106.104.80' (using password: YES)")
faker.factory: DEBUG: Not in REPL -> leaving logger event level as is.
raven.contrib.django.client.DjangoClient: DEBUG: Sending message of length 2286 to https://bugs.goibibo.com/api/7/store/
api.utils.base_utils: CRITICAL: Failed at get_config_params :::: (1045, "Access denied for user 'gouser'@'10.106.104.80' (using password: YES)")
--------------------- >> end captured logging << ---------------------]]></error></testcase><testcase classname="&lt;nose.suite" name="ContextSuite context=PromoCodeHelperTest&gt;:setup" time="0.000"><error type="django.db.utils.OperationalError" message="(1045, &quot;Access denied for user 'gouser'@'10.106.104.80' (using password: YES)&quot;)&#10;-------------------- &gt;&gt; begin captured logging &lt;&lt; --------------------&#10;raven.contrib.django.client.DjangoClient: DEBUG: Sending message of length 2296 to https://bugs.goibibo.com/api/7/store/&#10;api.utils.base_utils: CRITICAL: Failed at get_config_params :::: (1045, &quot;Access denied for user 'gouser'@'10.106.104.80' (using password: YES)&quot;)&#10;faker.factory: DEBUG: Not in REPL -&gt; leaving logger event level as is.&#10;raven.contrib.django.client.DjangoClient: DEBUG: Sending message of length 2286 to https://bugs.goibibo.com/api/7/store/&#10;api.utils.base_utils: CRITICAL: Failed at get_config_params :::: (1045, &quot;Access denied for user 'gouser'@'10.106.104.80' (using password: YES)&quot;)&#10;--------------------- &gt;&gt; end captured logging &lt;&lt; ---------------------"><![CDATA[  File "/usr/local/python3/lib/python3.6/site-packages/nose/suite.py", line 210, in run
    self.setUp()
  File "/usr/local/python3/lib/python3.6/site-packages/nose/suite.py", line 293, in setUp
    self.setupContext(ancestor)
  File "/usr/local/python3/lib/python3.6/site-packages/nose/suite.py", line 316, in setupContext
    try_run(context, names)
  File "/usr/local/python3/lib/python3.6/site-packages/nose/util.py", line 471, in try_run
    return func()
  File "/usr/local/python3/lib/python3.6/site-packages/django/test/testcases.py", line 1005, in setUpClass
    if not connections_support_transactions():
  File "/usr/local/python3/lib/python3.6/site-packages/django/test/testcases.py", line 970, in connections_support_transactions
    return all(conn.features.supports_transactions for conn in connections.all())
  File "/usr/local/python3/lib/python3.6/site-packages/django/test/testcases.py", line 970, in <genexpr>
    return all(conn.features.supports_transactions for conn in connections.all())
  File "/usr/local/python3/lib/python3.6/site-packages/django/utils/functional.py", line 37, in __get__
    res = instance.__dict__[self.name] = self.func(instance)
  File "/usr/local/python3/lib/python3.6/site-packages/django/db/backends/mysql/features.py", line 101, in supports_transactions
    return self._mysql_storage_engine != 'MyISAM'
  File "/usr/local/python3/lib/python3.6/site-packages/django/utils/functional.py", line 37, in __get__
    res = instance.__dict__[self.name] = self.func(instance)
  File "/usr/local/python3/lib/python3.6/site-packages/django/db/backends/mysql/features.py", line 57, in _mysql_storage_engine
    with self.connection.cursor() as cursor:
  File "/usr/local/python3/lib/python3.6/site-packages/django/db/backends/base/base.py", line 255, in cursor
    return self._cursor()
  File "/usr/local/python3/lib/python3.6/site-packages/django/db/backends/base/base.py", line 232, in _cursor
    self.ensure_connection()
  File "/usr/local/python3/lib/python3.6/site-packages/django/db/backends/base/base.py", line 216, in ensure_connection
    self.connect()
  File "/usr/local/python3/lib/python3.6/site-packages/django/db/utils.py", line 89, in __exit__
    raise dj_exc_value.with_traceback(traceback) from exc_value
  File "/usr/local/python3/lib/python3.6/site-packages/django/db/backends/base/base.py", line 216, in ensure_connection
    self.connect()
  File "/usr/local/python3/lib/python3.6/site-packages/django/db/backends/base/base.py", line 194, in connect
    self.connection = self.get_new_connection(conn_params)
  File "/usr/local/python3/lib/python3.6/site-packages/django/db/backends/mysql/base.py", line 227, in get_new_connection
    return Database.connect(**conn_params)
  File "/usr/local/python3/lib/python3.6/site-packages/MySQLdb/__init__.py", line 86, in Connect
    return Connection(*args, **kwargs)
  File "/usr/local/python3/lib/python3.6/site-packages/MySQLdb/connections.py", line 204, in __init__
    super(Connection, self).__init__(*args, **kwargs2)
(1045, "Access denied for user 'gouser'@'10.106.104.80' (using password: YES)")
-------------------- >> begin captured logging << --------------------
raven.contrib.django.client.DjangoClient: DEBUG: Sending message of length 2296 to https://bugs.goibibo.com/api/7/store/
api.utils.base_utils: CRITICAL: Failed at get_config_params :::: (1045, "Access denied for user 'gouser'@'10.106.104.80' (using password: YES)")
faker.factory: DEBUG: Not in REPL -> leaving logger event level as is.
raven.contrib.django.client.DjangoClient: DEBUG: Sending message of length 2286 to https://bugs.goibibo.com/api/7/store/
api.utils.base_utils: CRITICAL: Failed at get_config_params :::: (1045, "Access denied for user 'gouser'@'10.106.104.80' (using password: YES)")
--------------------- >> end captured logging << ---------------------]]></error></testcase><testcase classname="&lt;nose.suite" name="ContextSuite context=PromotionFactoryTest&gt;:setup" time="0.000"><error type="django.db.utils.OperationalError" message="(1045, &quot;Access denied for user 'gouser'@'10.106.104.80' (using password: YES)&quot;)&#10;-------------------- &gt;&gt; begin captured logging &lt;&lt; --------------------&#10;raven.contrib.django.client.DjangoClient: DEBUG: Sending message of length 2296 to https://bugs.goibibo.com/api/7/store/&#10;api.utils.base_utils: CRITICAL: Failed at get_config_params :::: (1045, &quot;Access denied for user 'gouser'@'10.106.104.80' (using password: YES)&quot;)&#10;faker.factory: DEBUG: Not in REPL -&gt; leaving logger event level as is.&#10;raven.contrib.django.client.DjangoClient: DEBUG: Sending message of length 2286 to https://bugs.goibibo.com/api/7/store/&#10;api.utils.base_utils: CRITICAL: Failed at get_config_params :::: (1045, &quot;Access denied for user 'gouser'@'10.106.104.80' (using password: YES)&quot;)&#10;--------------------- &gt;&gt; end captured logging &lt;&lt; ---------------------"><![CDATA[  File "/usr/local/python3/lib/python3.6/site-packages/nose/suite.py", line 210, in run
    self.setUp()
  File "/usr/local/python3/lib/python3.6/site-packages/nose/suite.py", line 293, in setUp
    self.setupContext(ancestor)
  File "/usr/local/python3/lib/python3.6/site-packages/nose/suite.py", line 316, in setupContext
    try_run(context, names)
  File "/usr/local/python3/lib/python3.6/site-packages/nose/util.py", line 471, in try_run
    return func()
  File "/usr/local/python3/lib/python3.6/site-packages/django/test/testcases.py", line 1005, in setUpClass
    if not connections_support_transactions():
  File "/usr/local/python3/lib/python3.6/site-packages/django/test/testcases.py", line 970, in connections_support_transactions
    return all(conn.features.supports_transactions for conn in connections.all())
  File "/usr/local/python3/lib/python3.6/site-packages/django/test/testcases.py", line 970, in <genexpr>
    return all(conn.features.supports_transactions for conn in connections.all())
  File "/usr/local/python3/lib/python3.6/site-packages/django/utils/functional.py", line 37, in __get__
    res = instance.__dict__[self.name] = self.func(instance)
  File "/usr/local/python3/lib/python3.6/site-packages/django/db/backends/mysql/features.py", line 101, in supports_transactions
    return self._mysql_storage_engine != 'MyISAM'
  File "/usr/local/python3/lib/python3.6/site-packages/django/utils/functional.py", line 37, in __get__
    res = instance.__dict__[self.name] = self.func(instance)
  File "/usr/local/python3/lib/python3.6/site-packages/django/db/backends/mysql/features.py", line 57, in _mysql_storage_engine
    with self.connection.cursor() as cursor:
  File "/usr/local/python3/lib/python3.6/site-packages/django/db/backends/base/base.py", line 255, in cursor
    return self._cursor()
  File "/usr/local/python3/lib/python3.6/site-packages/django/db/backends/base/base.py", line 232, in _cursor
    self.ensure_connection()
  File "/usr/local/python3/lib/python3.6/site-packages/django/db/backends/base/base.py", line 216, in ensure_connection
    self.connect()
  File "/usr/local/python3/lib/python3.6/site-packages/django/db/utils.py", line 89, in __exit__
    raise dj_exc_value.with_traceback(traceback) from exc_value
  File "/usr/local/python3/lib/python3.6/site-packages/django/db/backends/base/base.py", line 216, in ensure_connection
    self.connect()
  File "/usr/local/python3/lib/python3.6/site-packages/django/db/backends/base/base.py", line 194, in connect
    self.connection = self.get_new_connection(conn_params)
  File "/usr/local/python3/lib/python3.6/site-packages/django/db/backends/mysql/base.py", line 227, in get_new_connection
    return Database.connect(**conn_params)
  File "/usr/local/python3/lib/python3.6/site-packages/MySQLdb/__init__.py", line 86, in Connect
    return Connection(*args, **kwargs)
  File "/usr/local/python3/lib/python3.6/site-packages/MySQLdb/connections.py", line 204, in __init__
    super(Connection, self).__init__(*args, **kwargs2)
(1045, "Access denied for user 'gouser'@'10.106.104.80' (using password: YES)")
-------------------- >> begin captured logging << --------------------
raven.contrib.django.client.DjangoClient: DEBUG: Sending message of length 2296 to https://bugs.goibibo.com/api/7/store/
api.utils.base_utils: CRITICAL: Failed at get_config_params :::: (1045, "Access denied for user 'gouser'@'10.106.104.80' (using password: YES)")
faker.factory: DEBUG: Not in REPL -> leaving logger event level as is.
raven.contrib.django.client.DjangoClient: DEBUG: Sending message of length 2286 to https://bugs.goibibo.com/api/7/store/
api.utils.base_utils: CRITICAL: Failed at get_config_params :::: (1045, "Access denied for user 'gouser'@'10.106.104.80' (using password: YES)")
--------------------- >> end captured logging << ---------------------]]></error></testcase><testcase classname="&lt;nose.suite" name="ContextSuite context=TestTicketingProfiler&gt;:setup" time="0.000"><error type="django.db.utils.OperationalError" message="(1045, &quot;Access denied for user 'gouser'@'10.106.104.80' (using password: YES)&quot;)&#10;-------------------- &gt;&gt; begin captured logging &lt;&lt; --------------------&#10;raven.contrib.django.client.DjangoClient: DEBUG: Sending message of length 2296 to https://bugs.goibibo.com/api/7/store/&#10;api.utils.base_utils: CRITICAL: Failed at get_config_params :::: (1045, &quot;Access denied for user 'gouser'@'10.106.104.80' (using password: YES)&quot;)&#10;faker.factory: DEBUG: Not in REPL -&gt; leaving logger event level as is.&#10;raven.contrib.django.client.DjangoClient: DEBUG: Sending message of length 2286 to https://bugs.goibibo.com/api/7/store/&#10;api.utils.base_utils: CRITICAL: Failed at get_config_params :::: (1045, &quot;Access denied for user 'gouser'@'10.106.104.80' (using password: YES)&quot;)&#10;--------------------- &gt;&gt; end captured logging &lt;&lt; ---------------------"><![CDATA[  File "/usr/local/python3/lib/python3.6/site-packages/nose/suite.py", line 210, in run
    self.setUp()
  File "/usr/local/python3/lib/python3.6/site-packages/nose/suite.py", line 293, in setUp
    self.setupContext(ancestor)
  File "/usr/local/python3/lib/python3.6/site-packages/nose/suite.py", line 316, in setupContext
    try_run(context, names)
  File "/usr/local/python3/lib/python3.6/site-packages/nose/util.py", line 471, in try_run
    return func()
  File "/usr/local/python3/lib/python3.6/site-packages/django/test/testcases.py", line 1005, in setUpClass
    if not connections_support_transactions():
  File "/usr/local/python3/lib/python3.6/site-packages/django/test/testcases.py", line 970, in connections_support_transactions
    return all(conn.features.supports_transactions for conn in connections.all())
  File "/usr/local/python3/lib/python3.6/site-packages/django/test/testcases.py", line 970, in <genexpr>
    return all(conn.features.supports_transactions for conn in connections.all())
  File "/usr/local/python3/lib/python3.6/site-packages/django/utils/functional.py", line 37, in __get__
    res = instance.__dict__[self.name] = self.func(instance)
  File "/usr/local/python3/lib/python3.6/site-packages/django/db/backends/mysql/features.py", line 101, in supports_transactions
    return self._mysql_storage_engine != 'MyISAM'
  File "/usr/local/python3/lib/python3.6/site-packages/django/utils/functional.py", line 37, in __get__
    res = instance.__dict__[self.name] = self.func(instance)
  File "/usr/local/python3/lib/python3.6/site-packages/django/db/backends/mysql/features.py", line 57, in _mysql_storage_engine
    with self.connection.cursor() as cursor:
  File "/usr/local/python3/lib/python3.6/site-packages/django/db/backends/base/base.py", line 255, in cursor
    return self._cursor()
  File "/usr/local/python3/lib/python3.6/site-packages/django/db/backends/base/base.py", line 232, in _cursor
    self.ensure_connection()
  File "/usr/local/python3/lib/python3.6/site-packages/django/db/backends/base/base.py", line 216, in ensure_connection
    self.connect()
  File "/usr/local/python3/lib/python3.6/site-packages/django/db/utils.py", line 89, in __exit__
    raise dj_exc_value.with_traceback(traceback) from exc_value
  File "/usr/local/python3/lib/python3.6/site-packages/django/db/backends/base/base.py", line 216, in ensure_connection
    self.connect()
  File "/usr/local/python3/lib/python3.6/site-packages/django/db/backends/base/base.py", line 194, in connect
    self.connection = self.get_new_connection(conn_params)
  File "/usr/local/python3/lib/python3.6/site-packages/django/db/backends/mysql/base.py", line 227, in get_new_connection
    return Database.connect(**conn_params)
  File "/usr/local/python3/lib/python3.6/site-packages/MySQLdb/__init__.py", line 86, in Connect
    return Connection(*args, **kwargs)
  File "/usr/local/python3/lib/python3.6/site-packages/MySQLdb/connections.py", line 204, in __init__
    super(Connection, self).__init__(*args, **kwargs2)
(1045, "Access denied for user 'gouser'@'10.106.104.80' (using password: YES)")
-------------------- >> begin captured logging << --------------------
raven.contrib.django.client.DjangoClient: DEBUG: Sending message of length 2296 to https://bugs.goibibo.com/api/7/store/
api.utils.base_utils: CRITICAL: Failed at get_config_params :::: (1045, "Access denied for user 'gouser'@'10.106.104.80' (using password: YES)")
faker.factory: DEBUG: Not in REPL -> leaving logger event level as is.
raven.contrib.django.client.DjangoClient: DEBUG: Sending message of length 2286 to https://bugs.goibibo.com/api/7/store/
api.utils.base_utils: CRITICAL: Failed at get_config_params :::: (1045, "Access denied for user 'gouser'@'10.106.104.80' (using password: YES)")
--------------------- >> end captured logging << ---------------------]]></error></testcase><testcase classname="&lt;nose.suite" name="ContextSuite context=TestTierBenefitsHelper&gt;:setup" time="0.000"><error type="django.db.utils.OperationalError" message="(1045, &quot;Access denied for user 'gouser'@'10.106.104.80' (using password: YES)&quot;)&#10;-------------------- &gt;&gt; begin captured logging &lt;&lt; --------------------&#10;raven.contrib.django.client.DjangoClient: DEBUG: Sending message of length 2296 to https://bugs.goibibo.com/api/7/store/&#10;api.utils.base_utils: CRITICAL: Failed at get_config_params :::: (1045, &quot;Access denied for user 'gouser'@'10.106.104.80' (using password: YES)&quot;)&#10;faker.factory: DEBUG: Not in REPL -&gt; leaving logger event level as is.&#10;raven.contrib.django.client.DjangoClient: DEBUG: Sending message of length 2286 to https://bugs.goibibo.com/api/7/store/&#10;api.utils.base_utils: CRITICAL: Failed at get_config_params :::: (1045, &quot;Access denied for user 'gouser'@'10.106.104.80' (using password: YES)&quot;)&#10;--------------------- &gt;&gt; end captured logging &lt;&lt; ---------------------"><![CDATA[  File "/usr/local/python3/lib/python3.6/site-packages/nose/suite.py", line 210, in run
    self.setUp()
  File "/usr/local/python3/lib/python3.6/site-packages/nose/suite.py", line 293, in setUp
    self.setupContext(ancestor)
  File "/usr/local/python3/lib/python3.6/site-packages/nose/suite.py", line 316, in setupContext
    try_run(context, names)
  File "/usr/local/python3/lib/python3.6/site-packages/nose/util.py", line 471, in try_run
    return func()
  File "/usr/local/python3/lib/python3.6/site-packages/django/test/testcases.py", line 1005, in setUpClass
    if not connections_support_transactions():
  File "/usr/local/python3/lib/python3.6/site-packages/django/test/testcases.py", line 970, in connections_support_transactions
    return all(conn.features.supports_transactions for conn in connections.all())
  File "/usr/local/python3/lib/python3.6/site-packages/django/test/testcases.py", line 970, in <genexpr>
    return all(conn.features.supports_transactions for conn in connections.all())
  File "/usr/local/python3/lib/python3.6/site-packages/django/utils/functional.py", line 37, in __get__
    res = instance.__dict__[self.name] = self.func(instance)
  File "/usr/local/python3/lib/python3.6/site-packages/django/db/backends/mysql/features.py", line 101, in supports_transactions
    return self._mysql_storage_engine != 'MyISAM'
  File "/usr/local/python3/lib/python3.6/site-packages/django/utils/functional.py", line 37, in __get__
    res = instance.__dict__[self.name] = self.func(instance)
  File "/usr/local/python3/lib/python3.6/site-packages/django/db/backends/mysql/features.py", line 57, in _mysql_storage_engine
    with self.connection.cursor() as cursor:
  File "/usr/local/python3/lib/python3.6/site-packages/django/db/backends/base/base.py", line 255, in cursor
    return self._cursor()
  File "/usr/local/python3/lib/python3.6/site-packages/django/db/backends/base/base.py", line 232, in _cursor
    self.ensure_connection()
  File "/usr/local/python3/lib/python3.6/site-packages/django/db/backends/base/base.py", line 216, in ensure_connection
    self.connect()
  File "/usr/local/python3/lib/python3.6/site-packages/django/db/utils.py", line 89, in __exit__
    raise dj_exc_value.with_traceback(traceback) from exc_value
  File "/usr/local/python3/lib/python3.6/site-packages/django/db/backends/base/base.py", line 216, in ensure_connection
    self.connect()
  File "/usr/local/python3/lib/python3.6/site-packages/django/db/backends/base/base.py", line 194, in connect
    self.connection = self.get_new_connection(conn_params)
  File "/usr/local/python3/lib/python3.6/site-packages/django/db/backends/mysql/base.py", line 227, in get_new_connection
    return Database.connect(**conn_params)
  File "/usr/local/python3/lib/python3.6/site-packages/MySQLdb/__init__.py", line 86, in Connect
    return Connection(*args, **kwargs)
  File "/usr/local/python3/lib/python3.6/site-packages/MySQLdb/connections.py", line 204, in __init__
    super(Connection, self).__init__(*args, **kwargs2)
(1045, "Access denied for user 'gouser'@'10.106.104.80' (using password: YES)")
-------------------- >> begin captured logging << --------------------
raven.contrib.django.client.DjangoClient: DEBUG: Sending message of length 2296 to https://bugs.goibibo.com/api/7/store/
api.utils.base_utils: CRITICAL: Failed at get_config_params :::: (1045, "Access denied for user 'gouser'@'10.106.104.80' (using password: YES)")
faker.factory: DEBUG: Not in REPL -> leaving logger event level as is.
raven.contrib.django.client.DjangoClient: DEBUG: Sending message of length 2286 to https://bugs.goibibo.com/api/7/store/
api.utils.base_utils: CRITICAL: Failed at get_config_params :::: (1045, "Access denied for user 'gouser'@'10.106.104.80' (using password: YES)")
--------------------- >> end captured logging << ---------------------]]></error></testcase><testcase classname="&lt;nose.suite" name="ContextSuite context=FlightInfoParserTest&gt;:setup" time="0.000"><error type="django.db.utils.OperationalError" message="(1045, &quot;Access denied for user 'gouser'@'10.106.104.80' (using password: YES)&quot;)&#10;-------------------- &gt;&gt; begin captured logging &lt;&lt; --------------------&#10;raven.contrib.django.client.DjangoClient: DEBUG: Sending message of length 2296 to https://bugs.goibibo.com/api/7/store/&#10;api.utils.base_utils: CRITICAL: Failed at get_config_params :::: (1045, &quot;Access denied for user 'gouser'@'10.106.104.80' (using password: YES)&quot;)&#10;faker.factory: DEBUG: Not in REPL -&gt; leaving logger event level as is.&#10;raven.contrib.django.client.DjangoClient: DEBUG: Sending message of length 2286 to https://bugs.goibibo.com/api/7/store/&#10;api.utils.base_utils: CRITICAL: Failed at get_config_params :::: (1045, &quot;Access denied for user 'gouser'@'10.106.104.80' (using password: YES)&quot;)&#10;--------------------- &gt;&gt; end captured logging &lt;&lt; ---------------------"><![CDATA[  File "/usr/local/python3/lib/python3.6/site-packages/nose/suite.py", line 210, in run
    self.setUp()
  File "/usr/local/python3/lib/python3.6/site-packages/nose/suite.py", line 293, in setUp
    self.setupContext(ancestor)
  File "/usr/local/python3/lib/python3.6/site-packages/nose/suite.py", line 316, in setupContext
    try_run(context, names)
  File "/usr/local/python3/lib/python3.6/site-packages/nose/util.py", line 471, in try_run
    return func()
  File "/usr/local/python3/lib/python3.6/site-packages/django/test/testcases.py", line 1005, in setUpClass
    if not connections_support_transactions():
  File "/usr/local/python3/lib/python3.6/site-packages/django/test/testcases.py", line 970, in connections_support_transactions
    return all(conn.features.supports_transactions for conn in connections.all())
  File "/usr/local/python3/lib/python3.6/site-packages/django/test/testcases.py", line 970, in <genexpr>
    return all(conn.features.supports_transactions for conn in connections.all())
  File "/usr/local/python3/lib/python3.6/site-packages/django/utils/functional.py", line 37, in __get__
    res = instance.__dict__[self.name] = self.func(instance)
  File "/usr/local/python3/lib/python3.6/site-packages/django/db/backends/mysql/features.py", line 101, in supports_transactions
    return self._mysql_storage_engine != 'MyISAM'
  File "/usr/local/python3/lib/python3.6/site-packages/django/utils/functional.py", line 37, in __get__
    res = instance.__dict__[self.name] = self.func(instance)
  File "/usr/local/python3/lib/python3.6/site-packages/django/db/backends/mysql/features.py", line 57, in _mysql_storage_engine
    with self.connection.cursor() as cursor:
  File "/usr/local/python3/lib/python3.6/site-packages/django/db/backends/base/base.py", line 255, in cursor
    return self._cursor()
  File "/usr/local/python3/lib/python3.6/site-packages/django/db/backends/base/base.py", line 232, in _cursor
    self.ensure_connection()
  File "/usr/local/python3/lib/python3.6/site-packages/django/db/backends/base/base.py", line 216, in ensure_connection
    self.connect()
  File "/usr/local/python3/lib/python3.6/site-packages/django/db/utils.py", line 89, in __exit__
    raise dj_exc_value.with_traceback(traceback) from exc_value
  File "/usr/local/python3/lib/python3.6/site-packages/django/db/backends/base/base.py", line 216, in ensure_connection
    self.connect()
  File "/usr/local/python3/lib/python3.6/site-packages/django/db/backends/base/base.py", line 194, in connect
    self.connection = self.get_new_connection(conn_params)
  File "/usr/local/python3/lib/python3.6/site-packages/django/db/backends/mysql/base.py", line 227, in get_new_connection
    return Database.connect(**conn_params)
  File "/usr/local/python3/lib/python3.6/site-packages/MySQLdb/__init__.py", line 86, in Connect
    return Connection(*args, **kwargs)
  File "/usr/local/python3/lib/python3.6/site-packages/MySQLdb/connections.py", line 204, in __init__
    super(Connection, self).__init__(*args, **kwargs2)
(1045, "Access denied for user 'gouser'@'10.106.104.80' (using password: YES)")
-------------------- >> begin captured logging << --------------------
raven.contrib.django.client.DjangoClient: DEBUG: Sending message of length 2296 to https://bugs.goibibo.com/api/7/store/
api.utils.base_utils: CRITICAL: Failed at get_config_params :::: (1045, "Access denied for user 'gouser'@'10.106.104.80' (using password: YES)")
faker.factory: DEBUG: Not in REPL -> leaving logger event level as is.
raven.contrib.django.client.DjangoClient: DEBUG: Sending message of length 2286 to https://bugs.goibibo.com/api/7/store/
api.utils.base_utils: CRITICAL: Failed at get_config_params :::: (1045, "Access denied for user 'gouser'@'10.106.104.80' (using password: YES)")
--------------------- >> end captured logging << ---------------------]]></error></testcase><testcase classname="&lt;nose.suite" name="ContextSuite context=TourCodeParamParserTest&gt;:setup" time="0.000"><error type="django.db.utils.OperationalError" message="(1045, &quot;Access denied for user 'gouser'@'10.106.104.80' (using password: YES)&quot;)&#10;-------------------- &gt;&gt; begin captured logging &lt;&lt; --------------------&#10;raven.contrib.django.client.DjangoClient: DEBUG: Sending message of length 2296 to https://bugs.goibibo.com/api/7/store/&#10;api.utils.base_utils: CRITICAL: Failed at get_config_params :::: (1045, &quot;Access denied for user 'gouser'@'10.106.104.80' (using password: YES)&quot;)&#10;faker.factory: DEBUG: Not in REPL -&gt; leaving logger event level as is.&#10;raven.contrib.django.client.DjangoClient: DEBUG: Sending message of length 2286 to https://bugs.goibibo.com/api/7/store/&#10;api.utils.base_utils: CRITICAL: Failed at get_config_params :::: (1045, &quot;Access denied for user 'gouser'@'10.106.104.80' (using password: YES)&quot;)&#10;--------------------- &gt;&gt; end captured logging &lt;&lt; ---------------------"><![CDATA[  File "/usr/local/python3/lib/python3.6/site-packages/nose/suite.py", line 210, in run
    self.setUp()
  File "/usr/local/python3/lib/python3.6/site-packages/nose/suite.py", line 293, in setUp
    self.setupContext(ancestor)
  File "/usr/local/python3/lib/python3.6/site-packages/nose/suite.py", line 316, in setupContext
    try_run(context, names)
  File "/usr/local/python3/lib/python3.6/site-packages/nose/util.py", line 471, in try_run
    return func()
  File "/usr/local/python3/lib/python3.6/site-packages/django/test/testcases.py", line 1005, in setUpClass
    if not connections_support_transactions():
  File "/usr/local/python3/lib/python3.6/site-packages/django/test/testcases.py", line 970, in connections_support_transactions
    return all(conn.features.supports_transactions for conn in connections.all())
  File "/usr/local/python3/lib/python3.6/site-packages/django/test/testcases.py", line 970, in <genexpr>
    return all(conn.features.supports_transactions for conn in connections.all())
  File "/usr/local/python3/lib/python3.6/site-packages/django/utils/functional.py", line 37, in __get__
    res = instance.__dict__[self.name] = self.func(instance)
  File "/usr/local/python3/lib/python3.6/site-packages/django/db/backends/mysql/features.py", line 101, in supports_transactions
    return self._mysql_storage_engine != 'MyISAM'
  File "/usr/local/python3/lib/python3.6/site-packages/django/utils/functional.py", line 37, in __get__
    res = instance.__dict__[self.name] = self.func(instance)
  File "/usr/local/python3/lib/python3.6/site-packages/django/db/backends/mysql/features.py", line 57, in _mysql_storage_engine
    with self.connection.cursor() as cursor:
  File "/usr/local/python3/lib/python3.6/site-packages/django/db/backends/base/base.py", line 255, in cursor
    return self._cursor()
  File "/usr/local/python3/lib/python3.6/site-packages/django/db/backends/base/base.py", line 232, in _cursor
    self.ensure_connection()
  File "/usr/local/python3/lib/python3.6/site-packages/django/db/backends/base/base.py", line 216, in ensure_connection
    self.connect()
  File "/usr/local/python3/lib/python3.6/site-packages/django/db/utils.py", line 89, in __exit__
    raise dj_exc_value.with_traceback(traceback) from exc_value
  File "/usr/local/python3/lib/python3.6/site-packages/django/db/backends/base/base.py", line 216, in ensure_connection
    self.connect()
  File "/usr/local/python3/lib/python3.6/site-packages/django/db/backends/base/base.py", line 194, in connect
    self.connection = self.get_new_connection(conn_params)
  File "/usr/local/python3/lib/python3.6/site-packages/django/db/backends/mysql/base.py", line 227, in get_new_connection
    return Database.connect(**conn_params)
  File "/usr/local/python3/lib/python3.6/site-packages/MySQLdb/__init__.py", line 86, in Connect
    return Connection(*args, **kwargs)
  File "/usr/local/python3/lib/python3.6/site-packages/MySQLdb/connections.py", line 204, in __init__
    super(Connection, self).__init__(*args, **kwargs2)
(1045, "Access denied for user 'gouser'@'10.106.104.80' (using password: YES)")
-------------------- >> begin captured logging << --------------------
raven.contrib.django.client.DjangoClient: DEBUG: Sending message of length 2296 to https://bugs.goibibo.com/api/7/store/
api.utils.base_utils: CRITICAL: Failed at get_config_params :::: (1045, "Access denied for user 'gouser'@'10.106.104.80' (using password: YES)")
faker.factory: DEBUG: Not in REPL -> leaving logger event level as is.
raven.contrib.django.client.DjangoClient: DEBUG: Sending message of length 2286 to https://bugs.goibibo.com/api/7/store/
api.utils.base_utils: CRITICAL: Failed at get_config_params :::: (1045, "Access denied for user 'gouser'@'10.106.104.80' (using password: YES)")
--------------------- >> end captured logging << ---------------------]]></error></testcase><testcase classname="&lt;nose.suite" name="ContextSuite context=TestVoyager&gt;:setup" time="0.000"><error type="django.db.utils.OperationalError" message="(1045, &quot;Access denied for user 'gouser'@'10.106.104.80' (using password: YES)&quot;)&#10;-------------------- &gt;&gt; begin captured logging &lt;&lt; --------------------&#10;raven.contrib.django.client.DjangoClient: DEBUG: Sending message of length 2296 to https://bugs.goibibo.com/api/7/store/&#10;api.utils.base_utils: CRITICAL: Failed at get_config_params :::: (1045, &quot;Access denied for user 'gouser'@'10.106.104.80' (using password: YES)&quot;)&#10;faker.factory: DEBUG: Not in REPL -&gt; leaving logger event level as is.&#10;raven.contrib.django.client.DjangoClient: DEBUG: Sending message of length 2286 to https://bugs.goibibo.com/api/7/store/&#10;api.utils.base_utils: CRITICAL: Failed at get_config_params :::: (1045, &quot;Access denied for user 'gouser'@'10.106.104.80' (using password: YES)&quot;)&#10;--------------------- &gt;&gt; end captured logging &lt;&lt; ---------------------"><![CDATA[  File "/usr/local/python3/lib/python3.6/site-packages/nose/suite.py", line 210, in run
    self.setUp()
  File "/usr/local/python3/lib/python3.6/site-packages/nose/suite.py", line 293, in setUp
    self.setupContext(ancestor)
  File "/usr/local/python3/lib/python3.6/site-packages/nose/suite.py", line 316, in setupContext
    try_run(context, names)
  File "/usr/local/python3/lib/python3.6/site-packages/nose/util.py", line 471, in try_run
    return func()
  File "/usr/local/python3/lib/python3.6/site-packages/django/test/testcases.py", line 1005, in setUpClass
    if not connections_support_transactions():
  File "/usr/local/python3/lib/python3.6/site-packages/django/test/testcases.py", line 970, in connections_support_transactions
    return all(conn.features.supports_transactions for conn in connections.all())
  File "/usr/local/python3/lib/python3.6/site-packages/django/test/testcases.py", line 970, in <genexpr>
    return all(conn.features.supports_transactions for conn in connections.all())
  File "/usr/local/python3/lib/python3.6/site-packages/django/utils/functional.py", line 37, in __get__
    res = instance.__dict__[self.name] = self.func(instance)
  File "/usr/local/python3/lib/python3.6/site-packages/django/db/backends/mysql/features.py", line 101, in supports_transactions
    return self._mysql_storage_engine != 'MyISAM'
  File "/usr/local/python3/lib/python3.6/site-packages/django/utils/functional.py", line 37, in __get__
    res = instance.__dict__[self.name] = self.func(instance)
  File "/usr/local/python3/lib/python3.6/site-packages/django/db/backends/mysql/features.py", line 57, in _mysql_storage_engine
    with self.connection.cursor() as cursor:
  File "/usr/local/python3/lib/python3.6/site-packages/django/db/backends/base/base.py", line 255, in cursor
    return self._cursor()
  File "/usr/local/python3/lib/python3.6/site-packages/django/db/backends/base/base.py", line 232, in _cursor
    self.ensure_connection()
  File "/usr/local/python3/lib/python3.6/site-packages/django/db/backends/base/base.py", line 216, in ensure_connection
    self.connect()
  File "/usr/local/python3/lib/python3.6/site-packages/django/db/utils.py", line 89, in __exit__
    raise dj_exc_value.with_traceback(traceback) from exc_value
  File "/usr/local/python3/lib/python3.6/site-packages/django/db/backends/base/base.py", line 216, in ensure_connection
    self.connect()
  File "/usr/local/python3/lib/python3.6/site-packages/django/db/backends/base/base.py", line 194, in connect
    self.connection = self.get_new_connection(conn_params)
  File "/usr/local/python3/lib/python3.6/site-packages/django/db/backends/mysql/base.py", line 227, in get_new_connection
    return Database.connect(**conn_params)
  File "/usr/local/python3/lib/python3.6/site-packages/MySQLdb/__init__.py", line 86, in Connect
    return Connection(*args, **kwargs)
  File "/usr/local/python3/lib/python3.6/site-packages/MySQLdb/connections.py", line 204, in __init__
    super(Connection, self).__init__(*args, **kwargs2)
(1045, "Access denied for user 'gouser'@'10.106.104.80' (using password: YES)")
-------------------- >> begin captured logging << --------------------
raven.contrib.django.client.DjangoClient: DEBUG: Sending message of length 2296 to https://bugs.goibibo.com/api/7/store/
api.utils.base_utils: CRITICAL: Failed at get_config_params :::: (1045, "Access denied for user 'gouser'@'10.106.104.80' (using password: YES)")
faker.factory: DEBUG: Not in REPL -> leaving logger event level as is.
raven.contrib.django.client.DjangoClient: DEBUG: Sending message of length 2286 to https://bugs.goibibo.com/api/7/store/
api.utils.base_utils: CRITICAL: Failed at get_config_params :::: (1045, "Access denied for user 'gouser'@'10.106.104.80' (using password: YES)")
--------------------- >> end captured logging << ---------------------]]></error></testcase><testcase classname="&lt;nose.suite" name="ContextSuite context=TestVoyagerApi&gt;:setup" time="0.000"><error type="django.db.utils.OperationalError" message="(1045, &quot;Access denied for user 'gouser'@'10.106.104.80' (using password: YES)&quot;)&#10;-------------------- &gt;&gt; begin captured logging &lt;&lt; --------------------&#10;raven.contrib.django.client.DjangoClient: DEBUG: Sending message of length 2296 to https://bugs.goibibo.com/api/7/store/&#10;api.utils.base_utils: CRITICAL: Failed at get_config_params :::: (1045, &quot;Access denied for user 'gouser'@'10.106.104.80' (using password: YES)&quot;)&#10;faker.factory: DEBUG: Not in REPL -&gt; leaving logger event level as is.&#10;raven.contrib.django.client.DjangoClient: DEBUG: Sending message of length 2286 to https://bugs.goibibo.com/api/7/store/&#10;api.utils.base_utils: CRITICAL: Failed at get_config_params :::: (1045, &quot;Access denied for user 'gouser'@'10.106.104.80' (using password: YES)&quot;)&#10;--------------------- &gt;&gt; end captured logging &lt;&lt; ---------------------"><![CDATA[  File "/usr/local/python3/lib/python3.6/site-packages/nose/suite.py", line 210, in run
    self.setUp()
  File "/usr/local/python3/lib/python3.6/site-packages/nose/suite.py", line 293, in setUp
    self.setupContext(ancestor)
  File "/usr/local/python3/lib/python3.6/site-packages/nose/suite.py", line 316, in setupContext
    try_run(context, names)
  File "/usr/local/python3/lib/python3.6/site-packages/nose/util.py", line 471, in try_run
    return func()
  File "/usr/local/python3/lib/python3.6/site-packages/django/test/testcases.py", line 1005, in setUpClass
    if not connections_support_transactions():
  File "/usr/local/python3/lib/python3.6/site-packages/django/test/testcases.py", line 970, in connections_support_transactions
    return all(conn.features.supports_transactions for conn in connections.all())
  File "/usr/local/python3/lib/python3.6/site-packages/django/test/testcases.py", line 970, in <genexpr>
    return all(conn.features.supports_transactions for conn in connections.all())
  File "/usr/local/python3/lib/python3.6/site-packages/django/utils/functional.py", line 37, in __get__
    res = instance.__dict__[self.name] = self.func(instance)
  File "/usr/local/python3/lib/python3.6/site-packages/django/db/backends/mysql/features.py", line 101, in supports_transactions
    return self._mysql_storage_engine != 'MyISAM'
  File "/usr/local/python3/lib/python3.6/site-packages/django/utils/functional.py", line 37, in __get__
    res = instance.__dict__[self.name] = self.func(instance)
  File "/usr/local/python3/lib/python3.6/site-packages/django/db/backends/mysql/features.py", line 57, in _mysql_storage_engine
    with self.connection.cursor() as cursor:
  File "/usr/local/python3/lib/python3.6/site-packages/django/db/backends/base/base.py", line 255, in cursor
    return self._cursor()
  File "/usr/local/python3/lib/python3.6/site-packages/django/db/backends/base/base.py", line 232, in _cursor
    self.ensure_connection()
  File "/usr/local/python3/lib/python3.6/site-packages/django/db/backends/base/base.py", line 216, in ensure_connection
    self.connect()
  File "/usr/local/python3/lib/python3.6/site-packages/django/db/utils.py", line 89, in __exit__
    raise dj_exc_value.with_traceback(traceback) from exc_value
  File "/usr/local/python3/lib/python3.6/site-packages/django/db/backends/base/base.py", line 216, in ensure_connection
    self.connect()
  File "/usr/local/python3/lib/python3.6/site-packages/django/db/backends/base/base.py", line 194, in connect
    self.connection = self.get_new_connection(conn_params)
  File "/usr/local/python3/lib/python3.6/site-packages/django/db/backends/mysql/base.py", line 227, in get_new_connection
    return Database.connect(**conn_params)
  File "/usr/local/python3/lib/python3.6/site-packages/MySQLdb/__init__.py", line 86, in Connect
    return Connection(*args, **kwargs)
  File "/usr/local/python3/lib/python3.6/site-packages/MySQLdb/connections.py", line 204, in __init__
    super(Connection, self).__init__(*args, **kwargs2)
(1045, "Access denied for user 'gouser'@'10.106.104.80' (using password: YES)")
-------------------- >> begin captured logging << --------------------
raven.contrib.django.client.DjangoClient: DEBUG: Sending message of length 2296 to https://bugs.goibibo.com/api/7/store/
api.utils.base_utils: CRITICAL: Failed at get_config_params :::: (1045, "Access denied for user 'gouser'@'10.106.104.80' (using password: YES)")
faker.factory: DEBUG: Not in REPL -> leaving logger event level as is.
raven.contrib.django.client.DjangoClient: DEBUG: Sending message of length 2286 to https://bugs.goibibo.com/api/7/store/
api.utils.base_utils: CRITICAL: Failed at get_config_params :::: (1045, "Access denied for user 'gouser'@'10.106.104.80' (using password: YES)")
--------------------- >> end captured logging << ---------------------]]></error></testcase><testcase classname="nose.failure.Failure" name="runTest" time="0.003"><error type="builtins.ValueError" message="malformed node or string: {}&#10;-------------------- &gt;&gt; begin captured logging &lt;&lt; --------------------&#10;raven.contrib.django.client.DjangoClient: DEBUG: Sending message of length 2296 to https://bugs.goibibo.com/api/7/store/&#10;api.utils.base_utils: CRITICAL: Failed at get_config_params :::: (1045, &quot;Access denied for user 'gouser'@'10.106.104.80' (using password: YES)&quot;)&#10;faker.factory: DEBUG: Not in REPL -&gt; leaving logger event level as is.&#10;raven.contrib.django.client.DjangoClient: DEBUG: Sending message of length 2286 to https://bugs.goibibo.com/api/7/store/&#10;api.utils.base_utils: CRITICAL: Failed at get_config_params :::: (1045, &quot;Access denied for user 'gouser'@'10.106.104.80' (using password: YES)&quot;)&#10;--------------------- &gt;&gt; end captured logging &lt;&lt; ---------------------"><![CDATA[  File "/usr/local/python3/lib/python3.6/unittest/case.py", line 59, in testPartExecutor
    yield
  File "/usr/local/python3/lib/python3.6/unittest/case.py", line 601, in run
    testMethod()
  File "/usr/local/python3/lib/python3.6/site-packages/nose/failure.py", line 39, in runTest
    raise self.exc_val.with_traceback(self.tb)
  File "/usr/local/python3/lib/python3.6/site-packages/nose/loader.py", line 418, in loadTestsFromName
    addr.filename, addr.module)
  File "/usr/local/python3/lib/python3.6/site-packages/nose/importer.py", line 47, in importFromPath
    return self.importFromDir(dir_path, fqname)
  File "/usr/local/python3/lib/python3.6/site-packages/nose/importer.py", line 94, in importFromDir
    mod = load_module(part_fqname, fh, filename, desc)
  File "/usr/local/python3/lib/python3.6/imp.py", line 234, in load_module
    return load_source(name, filename, file)
  File "/usr/local/python3/lib/python3.6/imp.py", line 172, in load_source
    module = _load(spec)
  File "<frozen importlib._bootstrap>", line 675, in _load
  File "<frozen importlib._bootstrap>", line 655, in _load_unlocked
  File "<frozen importlib._bootstrap_external>", line 678, in exec_module
  File "<frozen importlib._bootstrap>", line 205, in _call_with_frames_removed
  File "/usr/local/goibibo/hulk/api/tests/unittest/test_ancillary_seats.py", line 3, in <module>
    from api import urls
  File "/usr/local/goibibo/hulk/api/urls.py", line 35, in <module>
    from api.post_booking.getprice_tentative import GetPriceTentative
  File "/usr/local/goibibo/hulk/api/post_booking/getprice_tentative.py", line 19, in <module>
    from api.submit.submit_api import Submit
  File "/usr/local/goibibo/hulk/api/submit/submit_api.py", line 33, in <module>
    from api.reprice.reprice_addons import RepriceAddons
  File "/usr/local/goibibo/hulk/api/reprice/reprice_addons.py", line 58, in <module>
    from .update_price import UpdatePrice
  File "/usr/local/goibibo/hulk/api/reprice/update_price.py", line 26, in <module>
    config_offer_keys_data = literal_eval(get_config_params('CUSTOM_OFFER_KEY_MAP', '{}'))
  File "/usr/local/python3/lib/python3.6/ast.py", line 85, in literal_eval
    return _convert(node_or_string)
  File "/usr/local/python3/lib/python3.6/ast.py", line 84, in _convert
    raise ValueError('malformed node or string: ' + repr(node))
malformed node or string: {}
-------------------- >> begin captured logging << --------------------
raven.contrib.django.client.DjangoClient: DEBUG: Sending message of length 2296 to https://bugs.goibibo.com/api/7/store/
api.utils.base_utils: CRITICAL: Failed at get_config_params :::: (1045, "Access denied for user 'gouser'@'10.106.104.80' (using password: YES)")
faker.factory: DEBUG: Not in REPL -> leaving logger event level as is.
raven.contrib.django.client.DjangoClient: DEBUG: Sending message of length 2286 to https://bugs.goibibo.com/api/7/store/
api.utils.base_utils: CRITICAL: Failed at get_config_params :::: (1045, "Access denied for user 'gouser'@'10.106.104.80' (using password: YES)")
--------------------- >> end captured logging << ---------------------]]></error></testcase><testcase classname="nose.failure.Failure" name="runTest" time="0.001"><error type="builtins.ValueError" message="malformed node or string: {}"><![CDATA[Traceback (most recent call last):
  File "/usr/local/python3/lib/python3.6/unittest/case.py", line 59, in testPartExecutor
    yield
  File "/usr/local/python3/lib/python3.6/unittest/case.py", line 601, in run
    testMethod()
  File "/usr/local/python3/lib/python3.6/site-packages/nose/failure.py", line 39, in runTest
    raise self.exc_val.with_traceback(self.tb)
  File "/usr/local/python3/lib/python3.6/site-packages/nose/loader.py", line 418, in loadTestsFromName
    addr.filename, addr.module)
  File "/usr/local/python3/lib/python3.6/site-packages/nose/importer.py", line 47, in importFromPath
    return self.importFromDir(dir_path, fqname)
  File "/usr/local/python3/lib/python3.6/site-packages/nose/importer.py", line 94, in importFromDir
    mod = load_module(part_fqname, fh, filename, desc)
  File "/usr/local/python3/lib/python3.6/imp.py", line 234, in load_module
    return load_source(name, filename, file)
  File "/usr/local/python3/lib/python3.6/imp.py", line 172, in load_source
    module = _load(spec)
  File "<frozen importlib._bootstrap>", line 675, in _load
  File "<frozen importlib._bootstrap>", line 655, in _load_unlocked
  File "<frozen importlib._bootstrap_external>", line 678, in exec_module
  File "<frozen importlib._bootstrap>", line 205, in _call_with_frames_removed
  File "/usr/local/goibibo/hulk/api/tests/unittest/test_flight_models.py", line 6, in <module>
    from api import urls
  File "/usr/local/goibibo/hulk/api/urls.py", line 35, in <module>
    from api.post_booking.getprice_tentative import GetPriceTentative
  File "/usr/local/goibibo/hulk/api/post_booking/getprice_tentative.py", line 19, in <module>
    from api.submit.submit_api import Submit
  File "/usr/local/goibibo/hulk/api/submit/submit_api.py", line 33, in <module>
    from api.reprice.reprice_addons import RepriceAddons
  File "/usr/local/goibibo/hulk/api/reprice/reprice_addons.py", line 58, in <module>
    from .update_price import UpdatePrice
  File "/usr/local/goibibo/hulk/api/reprice/update_price.py", line 26, in <module>
    config_offer_keys_data = literal_eval(get_config_params('CUSTOM_OFFER_KEY_MAP', '{}'))
  File "/usr/local/python3/lib/python3.6/ast.py", line 85, in literal_eval
    return _convert(node_or_string)
  File "/usr/local/python3/lib/python3.6/ast.py", line 84, in _convert
    raise ValueError('malformed node or string: ' + repr(node))
ValueError: malformed node or string: {}
]]></error></testcase></testsuite>